[2020-11-19 09:55:02,546][Thread-6:8700][task_id:django.request][log.py:230][ERROR][Internal Server Error: /Run_Case/]
Traceback (most recent call last):
  File "E:\PycharmProjects\yyapi\venv\lib\site-packages\django\core\handlers\exception.py", line 47, in inner
    response = get_response(request)
  File "E:\PycharmProjects\yyapi\venv\lib\site-packages\django\core\handlers\base.py", line 179, in _get_response
    response = wrapped_callback(request, *callback_args, **callback_kwargs)
  File "E:\PycharmProjects\yyapi\MyApp\views.py", line 830, in Run_Case
    run(Case_id, Case.name, steps)
  File "E:\PycharmProjects\yyapi\MyApp\run_case.py", line 29, in run
    make_def(steps)
  File "E:\PycharmProjects\yyapi\MyApp\run_case.py", line 23, in make_def
    setattr(Test, 'test_'+str(steps[i].index).zfill(3), make_defself(steps[i]))
  File "E:\PycharmProjects\yyapi\MyApp\run_case.py", line 18, in make_defself
    return tool()
TypeError: tool() missing 1 required positional argument: 'self'
[2020-11-24 10:09:15,687][Thread-7:9696][task_id:django.request][log.py:230][ERROR][Internal Server Error: /child/P_apis.html/1//]
Traceback (most recent call last):
  File "E:\PycharmProjects\yyapi\venv\lib\site-packages\django\core\handlers\exception.py", line 47, in inner
    response = get_response(request)
  File "E:\PycharmProjects\yyapi\venv\lib\site-packages\django\core\handlers\base.py", line 179, in _get_response
    response = wrapped_callback(request, *callback_args, **callback_kwargs)
  File "E:\PycharmProjects\yyapi\MyApp\views.py", line 69, in child
    res = child_json(eid, oid, ooid)
  File "E:\PycharmProjects\yyapi\MyApp\views.py", line 107, in child_json
    i.short_url = i.api_url.split('?')[0][:50]
AttributeError: 'NoneType' object has no attribute 'split'
[2020-11-24 10:09:18,938][Thread-8:17920][task_id:django.request][log.py:230][ERROR][Internal Server Error: /child/P_apis.html/1//]
Traceback (most recent call last):
  File "E:\PycharmProjects\yyapi\venv\lib\site-packages\django\core\handlers\exception.py", line 47, in inner
    response = get_response(request)
  File "E:\PycharmProjects\yyapi\venv\lib\site-packages\django\core\handlers\base.py", line 179, in _get_response
    response = wrapped_callback(request, *callback_args, **callback_kwargs)
  File "E:\PycharmProjects\yyapi\MyApp\views.py", line 69, in child
    res = child_json(eid, oid, ooid)
  File "E:\PycharmProjects\yyapi\MyApp\views.py", line 107, in child_json
    i.short_url = i.api_url.split('?')[0][:50]
AttributeError: 'NoneType' object has no attribute 'split'
[2020-11-24 10:09:19,649][Thread-9:17464][task_id:django.request][log.py:230][ERROR][Internal Server Error: /child/P_apis.html/1//]
Traceback (most recent call last):
  File "E:\PycharmProjects\yyapi\venv\lib\site-packages\django\core\handlers\exception.py", line 47, in inner
    response = get_response(request)
  File "E:\PycharmProjects\yyapi\venv\lib\site-packages\django\core\handlers\base.py", line 179, in _get_response
    response = wrapped_callback(request, *callback_args, **callback_kwargs)
  File "E:\PycharmProjects\yyapi\MyApp\views.py", line 69, in child
    res = child_json(eid, oid, ooid)
  File "E:\PycharmProjects\yyapi\MyApp\views.py", line 107, in child_json
    i.short_url = i.api_url.split('?')[0][:50]
AttributeError: 'NoneType' object has no attribute 'split'
[2020-11-24 10:09:20,325][Thread-10:12708][task_id:django.request][log.py:230][ERROR][Internal Server Error: /child/P_apis.html/1//]
Traceback (most recent call last):
  File "E:\PycharmProjects\yyapi\venv\lib\site-packages\django\core\handlers\exception.py", line 47, in inner
    response = get_response(request)
  File "E:\PycharmProjects\yyapi\venv\lib\site-packages\django\core\handlers\base.py", line 179, in _get_response
    response = wrapped_callback(request, *callback_args, **callback_kwargs)
  File "E:\PycharmProjects\yyapi\MyApp\views.py", line 69, in child
    res = child_json(eid, oid, ooid)
  File "E:\PycharmProjects\yyapi\MyApp\views.py", line 107, in child_json
    i.short_url = i.api_url.split('?')[0][:50]
AttributeError: 'NoneType' object has no attribute 'split'
[2020-11-24 10:09:20,878][Thread-11:15184][task_id:django.request][log.py:230][ERROR][Internal Server Error: /child/P_apis.html/1//]
Traceback (most recent call last):
  File "E:\PycharmProjects\yyapi\venv\lib\site-packages\django\core\handlers\exception.py", line 47, in inner
    response = get_response(request)
  File "E:\PycharmProjects\yyapi\venv\lib\site-packages\django\core\handlers\base.py", line 179, in _get_response
    response = wrapped_callback(request, *callback_args, **callback_kwargs)
  File "E:\PycharmProjects\yyapi\MyApp\views.py", line 69, in child
    res = child_json(eid, oid, ooid)
  File "E:\PycharmProjects\yyapi\MyApp\views.py", line 107, in child_json
    i.short_url = i.api_url.split('?')[0][:50]
AttributeError: 'NoneType' object has no attribute 'split'
[2020-11-24 10:29:09,747][Thread-14:11080][task_id:django.request][log.py:230][ERROR][Internal Server Error: /child/P_apis.html/1//]
Traceback (most recent call last):
  File "E:\PycharmProjects\yyapi\venv\lib\site-packages\django\core\handlers\exception.py", line 47, in inner
    response = get_response(request)
  File "E:\PycharmProjects\yyapi\venv\lib\site-packages\django\core\handlers\base.py", line 179, in _get_response
    response = wrapped_callback(request, *callback_args, **callback_kwargs)
  File "E:\PycharmProjects\yyapi\MyApp\views.py", line 69, in child
    res = child_json(eid, oid, ooid)
  File "E:\PycharmProjects\yyapi\MyApp\views.py", line 107, in child_json
    i.short_url = i.api_url.split('?')[0][:50]
AttributeError: 'NoneType' object has no attribute 'split'
[2020-11-24 10:29:11,058][Thread-14:11080][task_id:django.request][log.py:230][ERROR][Internal Server Error: /child/P_apis.html/1//]
Traceback (most recent call last):
  File "E:\PycharmProjects\yyapi\venv\lib\site-packages\django\core\handlers\exception.py", line 47, in inner
    response = get_response(request)
  File "E:\PycharmProjects\yyapi\venv\lib\site-packages\django\core\handlers\base.py", line 179, in _get_response
    response = wrapped_callback(request, *callback_args, **callback_kwargs)
  File "E:\PycharmProjects\yyapi\MyApp\views.py", line 69, in child
    res = child_json(eid, oid, ooid)
  File "E:\PycharmProjects\yyapi\MyApp\views.py", line 107, in child_json
    i.short_url = i.api_url.split('?')[0][:50]
AttributeError: 'NoneType' object has no attribute 'split'
[2020-11-24 10:35:07,991][Thread-7:14788][task_id:django.request][log.py:230][ERROR][Internal Server Error: /child/P_apis.html/1//]
Traceback (most recent call last):
  File "E:\PycharmProjects\yyapi\venv\lib\site-packages\django\core\handlers\exception.py", line 47, in inner
    response = get_response(request)
  File "E:\PycharmProjects\yyapi\venv\lib\site-packages\django\core\handlers\base.py", line 179, in _get_response
    response = wrapped_callback(request, *callback_args, **callback_kwargs)
  File "E:\PycharmProjects\yyapi\MyApp\views.py", line 69, in child
    res = child_json(eid, oid, ooid)
  File "E:\PycharmProjects\yyapi\MyApp\views.py", line 107, in child_json
    i.short_url = i.api_url.split('?')[0][:50]
AttributeError: 'NoneType' object has no attribute 'split'
[2020-11-24 10:38:37,160][Thread-12:10556][task_id:django.request][log.py:230][ERROR][Internal Server Error: /child/P_apis.html/1//]
Traceback (most recent call last):
  File "E:\PycharmProjects\yyapi\venv\lib\site-packages\django\core\handlers\exception.py", line 47, in inner
    response = get_response(request)
  File "E:\PycharmProjects\yyapi\venv\lib\site-packages\django\core\handlers\base.py", line 179, in _get_response
    response = wrapped_callback(request, *callback_args, **callback_kwargs)
  File "E:\PycharmProjects\yyapi\MyApp\views.py", line 69, in child
    res = child_json(eid, oid, ooid)
  File "E:\PycharmProjects\yyapi\MyApp\views.py", line 107, in child_json
    i.short_url = i.api_url.split('?')[0][:50]
AttributeError: 'NoneType' object has no attribute 'split'
[2020-11-24 10:39:08,634][Thread-14:6944][task_id:django.request][log.py:230][ERROR][Internal Server Error: /child/P_apis.html/1//]
Traceback (most recent call last):
  File "E:\PycharmProjects\yyapi\venv\lib\site-packages\django\core\handlers\exception.py", line 47, in inner
    response = get_response(request)
  File "E:\PycharmProjects\yyapi\venv\lib\site-packages\django\core\handlers\base.py", line 179, in _get_response
    response = wrapped_callback(request, *callback_args, **callback_kwargs)
  File "E:\PycharmProjects\yyapi\MyApp\views.py", line 69, in child
    res = child_json(eid, oid, ooid)
  File "E:\PycharmProjects\yyapi\MyApp\views.py", line 107, in child_json
    i.short_url = i.api_url.split('?')[0][:50]
AttributeError: 'NoneType' object has no attribute 'split'
[2020-11-24 10:40:16,255][Thread-7:6724][task_id:django.request][log.py:230][ERROR][Internal Server Error: /child/P_apis.html/1//]
Traceback (most recent call last):
  File "E:\PycharmProjects\yyapi\venv\lib\site-packages\django\core\handlers\exception.py", line 47, in inner
    response = get_response(request)
  File "E:\PycharmProjects\yyapi\venv\lib\site-packages\django\core\handlers\base.py", line 179, in _get_response
    response = wrapped_callback(request, *callback_args, **callback_kwargs)
  File "E:\PycharmProjects\yyapi\MyApp\views.py", line 69, in child
    res = child_json(eid, oid, ooid)
  File "E:\PycharmProjects\yyapi\MyApp\views.py", line 108, in child_json
    i.short_url = i.api_url.split('?')[0][:50]
AttributeError: 'NoneType' object has no attribute 'split'
[2020-11-24 10:40:33,736][Thread-8:8608][task_id:django.request][log.py:230][ERROR][Internal Server Error: /child/P_apis.html/1//]
Traceback (most recent call last):
  File "E:\PycharmProjects\yyapi\venv\lib\site-packages\django\core\handlers\exception.py", line 47, in inner
    response = get_response(request)
  File "E:\PycharmProjects\yyapi\venv\lib\site-packages\django\core\handlers\base.py", line 179, in _get_response
    response = wrapped_callback(request, *callback_args, **callback_kwargs)
  File "E:\PycharmProjects\yyapi\MyApp\views.py", line 69, in child
    res = child_json(eid, oid, ooid)
  File "E:\PycharmProjects\yyapi\MyApp\views.py", line 108, in child_json
    i.short_url = i.api_url.split('?')[0][:50]
AttributeError: 'NoneType' object has no attribute 'split'
[2020-11-24 10:40:36,243][Thread-7:3924][task_id:django.request][log.py:230][ERROR][Internal Server Error: /child/P_apis.html/1//]
Traceback (most recent call last):
  File "E:\PycharmProjects\yyapi\venv\lib\site-packages\django\core\handlers\exception.py", line 47, in inner
    response = get_response(request)
  File "E:\PycharmProjects\yyapi\venv\lib\site-packages\django\core\handlers\base.py", line 179, in _get_response
    response = wrapped_callback(request, *callback_args, **callback_kwargs)
  File "E:\PycharmProjects\yyapi\MyApp\views.py", line 69, in child
    res = child_json(eid, oid, ooid)
  File "E:\PycharmProjects\yyapi\MyApp\views.py", line 108, in child_json
    i.short_url = i.api_url.split('?')[0][:50]
AttributeError: 'NoneType' object has no attribute 'split'
[2020-11-24 10:41:07,387][Thread-12:4960][task_id:django.request][log.py:230][ERROR][Internal Server Error: /admin/MyApp/db_apis/11/change/]
Traceback (most recent call last):
  File "E:\PycharmProjects\yyapi\venv\lib\site-packages\django\core\handlers\exception.py", line 47, in inner
    response = get_response(request)
  File "E:\PycharmProjects\yyapi\venv\lib\site-packages\django\core\handlers\base.py", line 202, in _get_response
    response = response.render()
  File "E:\PycharmProjects\yyapi\venv\lib\site-packages\django\template\response.py", line 105, in render
    self.content = self.rendered_content
  File "E:\PycharmProjects\yyapi\venv\lib\site-packages\django\template\response.py", line 83, in rendered_content
    return template.render(context, self._request)
  File "E:\PycharmProjects\yyapi\venv\lib\site-packages\django\template\backends\django.py", line 61, in render
    return self.template.render(context)
  File "E:\PycharmProjects\yyapi\venv\lib\site-packages\django\template\base.py", line 170, in render
    return self._render(context)
  File "E:\PycharmProjects\yyapi\venv\lib\site-packages\django\template\base.py", line 162, in _render
    return self.nodelist.render(context)
  File "E:\PycharmProjects\yyapi\venv\lib\site-packages\django\template\base.py", line 938, in render
    bit = node.render_annotated(context)
  File "E:\PycharmProjects\yyapi\venv\lib\site-packages\django\template\base.py", line 905, in render_annotated
    return self.render(context)
  File "E:\PycharmProjects\yyapi\venv\lib\site-packages\django\template\loader_tags.py", line 150, in render
    return compiled_parent._render(context)
  File "E:\PycharmProjects\yyapi\venv\lib\site-packages\django\template\base.py", line 162, in _render
    return self.nodelist.render(context)
  File "E:\PycharmProjects\yyapi\venv\lib\site-packages\django\template\base.py", line 938, in render
    bit = node.render_annotated(context)
  File "E:\PycharmProjects\yyapi\venv\lib\site-packages\django\template\base.py", line 905, in render_annotated
    return self.render(context)
  File "E:\PycharmProjects\yyapi\venv\lib\site-packages\django\template\loader_tags.py", line 150, in render
    return compiled_parent._render(context)
  File "E:\PycharmProjects\yyapi\venv\lib\site-packages\django\template\base.py", line 162, in _render
    return self.nodelist.render(context)
  File "E:\PycharmProjects\yyapi\venv\lib\site-packages\django\template\base.py", line 938, in render
    bit = node.render_annotated(context)
  File "E:\PycharmProjects\yyapi\venv\lib\site-packages\django\template\base.py", line 905, in render_annotated
    return self.render(context)
  File "E:\PycharmProjects\yyapi\venv\lib\site-packages\django\template\defaulttags.py", line 312, in render
    return nodelist.render(context)
  File "E:\PycharmProjects\yyapi\venv\lib\site-packages\django\template\base.py", line 938, in render
    bit = node.render_annotated(context)
  File "E:\PycharmProjects\yyapi\venv\lib\site-packages\django\template\base.py", line 905, in render_annotated
    return self.render(context)
  File "E:\PycharmProjects\yyapi\venv\lib\site-packages\django\template\loader_tags.py", line 62, in render
    result = block.nodelist.render(context)
  File "E:\PycharmProjects\yyapi\venv\lib\site-packages\django\template\base.py", line 938, in render
    bit = node.render_annotated(context)
  File "E:\PycharmProjects\yyapi\venv\lib\site-packages\django\template\base.py", line 905, in render_annotated
    return self.render(context)
  File "E:\PycharmProjects\yyapi\venv\lib\site-packages\django\template\defaulttags.py", line 312, in render
    return nodelist.render(context)
  File "E:\PycharmProjects\yyapi\venv\lib\site-packages\django\template\base.py", line 938, in render
    bit = node.render_annotated(context)
  File "E:\PycharmProjects\yyapi\venv\lib\site-packages\django\template\base.py", line 905, in render_annotated
    return self.render(context)
  File "E:\PycharmProjects\yyapi\venv\lib\site-packages\django\template\base.py", line 988, in render
    output = self.filter_expression.resolve(context)
  File "E:\PycharmProjects\yyapi\venv\lib\site-packages\django\template\base.py", line 698, in resolve
    new_obj = func(obj, *arg_vals)
  File "E:\PycharmProjects\yyapi\venv\lib\site-packages\django\template\defaultfilters.py", line 42, in _dec
    args[0] = str(args[0])
TypeError: __str__ returned non-string (type NoneType)
[2020-12-09 20:21:13,385][Thread-6:21360][task_id:django.request][log.py:230][ERROR][Internal Server Error: /Api_save/]
Traceback (most recent call last):
  File "E:\PycharmProjects\yyapi\venv\lib\site-packages\django\utils\datastructures.py", line 76, in __getitem__
    list_ = super().__getitem__(key)
KeyError: 'ts-project_headers'

During handling of the above exception, another exception occurred:

Traceback (most recent call last):
  File "E:\PycharmProjects\yyapi\venv\lib\site-packages\django\core\handlers\exception.py", line 47, in inner
    response = get_response(request)
  File "E:\PycharmProjects\yyapi\venv\lib\site-packages\django\core\handlers\base.py", line 179, in _get_response
    response = wrapped_callback(request, *callback_args, **callback_kwargs)
  File "E:\PycharmProjects\yyapi\MyApp\views.py", line 355, in Api_save
    ts_project_headers = request.GET['ts-project_headers']
  File "E:\PycharmProjects\yyapi\venv\lib\site-packages\django\utils\datastructures.py", line 78, in __getitem__
    raise MultiValueDictKeyError(key)
django.utils.datastructures.MultiValueDictKeyError: 'ts-project_headers'
[2020-12-09 20:21:23,452][Thread-6:21360][task_id:django.request][log.py:230][ERROR][Internal Server Error: /Api_save/]
Traceback (most recent call last):
  File "E:\PycharmProjects\yyapi\venv\lib\site-packages\django\utils\datastructures.py", line 76, in __getitem__
    list_ = super().__getitem__(key)
KeyError: 'ts-project_headers'

During handling of the above exception, another exception occurred:

Traceback (most recent call last):
  File "E:\PycharmProjects\yyapi\venv\lib\site-packages\django\core\handlers\exception.py", line 47, in inner
    response = get_response(request)
  File "E:\PycharmProjects\yyapi\venv\lib\site-packages\django\core\handlers\base.py", line 179, in _get_response
    response = wrapped_callback(request, *callback_args, **callback_kwargs)
  File "E:\PycharmProjects\yyapi\MyApp\views.py", line 355, in Api_save
    ts_project_headers = request.GET['ts-project_headers']
  File "E:\PycharmProjects\yyapi\venv\lib\site-packages\django\utils\datastructures.py", line 78, in __getitem__
    raise MultiValueDictKeyError(key)
django.utils.datastructures.MultiValueDictKeyError: 'ts-project_headers'
[2020-12-09 20:21:36,577][Thread-7:1048][task_id:django.request][log.py:230][ERROR][Internal Server Error: /Api_save/]
Traceback (most recent call last):
  File "E:\PycharmProjects\yyapi\venv\lib\site-packages\django\utils\datastructures.py", line 76, in __getitem__
    list_ = super().__getitem__(key)
KeyError: 'ts-project_headers'

During handling of the above exception, another exception occurred:

Traceback (most recent call last):
  File "E:\PycharmProjects\yyapi\venv\lib\site-packages\django\core\handlers\exception.py", line 47, in inner
    response = get_response(request)
  File "E:\PycharmProjects\yyapi\venv\lib\site-packages\django\core\handlers\base.py", line 179, in _get_response
    response = wrapped_callback(request, *callback_args, **callback_kwargs)
  File "E:\PycharmProjects\yyapi\MyApp\views.py", line 355, in Api_save
    ts_project_headers = request.GET['ts-project_headers']
  File "E:\PycharmProjects\yyapi\venv\lib\site-packages\django\utils\datastructures.py", line 78, in __getitem__
    raise MultiValueDictKeyError(key)
django.utils.datastructures.MultiValueDictKeyError: 'ts-project_headers'
[2020-12-09 20:22:08,134][Thread-7:1048][task_id:django.request][log.py:230][ERROR][Internal Server Error: /Api_save/]
Traceback (most recent call last):
  File "E:\PycharmProjects\yyapi\venv\lib\site-packages\django\utils\datastructures.py", line 76, in __getitem__
    list_ = super().__getitem__(key)
KeyError: 'ts-project_headers'

During handling of the above exception, another exception occurred:

Traceback (most recent call last):
  File "E:\PycharmProjects\yyapi\venv\lib\site-packages\django\core\handlers\exception.py", line 47, in inner
    response = get_response(request)
  File "E:\PycharmProjects\yyapi\venv\lib\site-packages\django\core\handlers\base.py", line 179, in _get_response
    response = wrapped_callback(request, *callback_args, **callback_kwargs)
  File "E:\PycharmProjects\yyapi\MyApp\views.py", line 355, in Api_save
    ts_project_headers = request.GET['ts-project_headers']
  File "E:\PycharmProjects\yyapi\venv\lib\site-packages\django\utils\datastructures.py", line 78, in __getitem__
    raise MultiValueDictKeyError(key)
django.utils.datastructures.MultiValueDictKeyError: 'ts-project_headers'
[2020-12-09 20:22:13,894][Thread-7:1048][task_id:django.request][log.py:230][ERROR][Internal Server Error: /Api_save/]
Traceback (most recent call last):
  File "E:\PycharmProjects\yyapi\venv\lib\site-packages\django\utils\datastructures.py", line 76, in __getitem__
    list_ = super().__getitem__(key)
KeyError: 'ts-project_headers'

During handling of the above exception, another exception occurred:

Traceback (most recent call last):
  File "E:\PycharmProjects\yyapi\venv\lib\site-packages\django\core\handlers\exception.py", line 47, in inner
    response = get_response(request)
  File "E:\PycharmProjects\yyapi\venv\lib\site-packages\django\core\handlers\base.py", line 179, in _get_response
    response = wrapped_callback(request, *callback_args, **callback_kwargs)
  File "E:\PycharmProjects\yyapi\MyApp\views.py", line 355, in Api_save
    ts_project_headers = request.GET['ts-project_headers']
  File "E:\PycharmProjects\yyapi\venv\lib\site-packages\django\utils\datastructures.py", line 78, in __getitem__
    raise MultiValueDictKeyError(key)
django.utils.datastructures.MultiValueDictKeyError: 'ts-project_headers'
[2020-12-22 15:51:20,482][Thread-35:1720][task_id:django.request][log.py:230][ERROR][Internal Server Error: /save_project_host/]
Traceback (most recent call last):
  File "E:\PycharmProjects\yyapi\venv\lib\site-packages\django\utils\datastructures.py", line 76, in __getitem__
    list_ = super().__getitem__(key)
KeyError: 'req_host'

During handling of the above exception, another exception occurred:

Traceback (most recent call last):
  File "E:\PycharmProjects\yyapi\venv\lib\site-packages\django\core\handlers\exception.py", line 47, in inner
    response = get_response(request)
  File "E:\PycharmProjects\yyapi\venv\lib\site-packages\django\core\handlers\base.py", line 179, in _get_response
    response = wrapped_callback(request, *callback_args, **callback_kwargs)
  File "E:\PycharmProjects\yyapi\MyApp\views.py", line 918, in save_project_host
    req_hosts = request.GET['req_host']
  File "E:\PycharmProjects\yyapi\venv\lib\site-packages\django\utils\datastructures.py", line 78, in __getitem__
    raise MultiValueDictKeyError(key)
django.utils.datastructures.MultiValueDictKeyError: 'req_host'
[2020-12-22 15:52:48,271][Thread-6:13316][task_id:django.request][log.py:230][ERROR][Internal Server Error: /save_project_host/]
Traceback (most recent call last):
  File "E:\PycharmProjects\yyapi\venv\lib\site-packages\django\core\handlers\exception.py", line 47, in inner
    response = get_response(request)
  File "E:\PycharmProjects\yyapi\venv\lib\site-packages\django\core\handlers\base.py", line 179, in _get_response
    response = wrapped_callback(request, *callback_args, **callback_kwargs)
  File "E:\PycharmProjects\yyapi\MyApp\views.py", line 928, in save_project_host
    DB_project_header.objects.create(project_id=project_id, name=names[i], host=hosts[i])
  File "E:\PycharmProjects\yyapi\venv\lib\site-packages\django\db\models\manager.py", line 85, in manager_method
    return getattr(self.get_queryset(), name)(*args, **kwargs)
  File "E:\PycharmProjects\yyapi\venv\lib\site-packages\django\db\models\query.py", line 445, in create
    obj = self.model(**kwargs)
  File "E:\PycharmProjects\yyapi\venv\lib\site-packages\django\db\models\base.py", line 501, in __init__
    raise TypeError("%s() got an unexpected keyword argument '%s'" % (cls.__name__, kwarg))
TypeError: DB_project_header() got an unexpected keyword argument 'host'
[2020-12-22 15:58:36,898][Thread-7:17156][task_id:django.request][log.py:230][ERROR][Internal Server Error: /save_project_host/]
Traceback (most recent call last):
  File "E:\PycharmProjects\yyapi\venv\lib\site-packages\django\core\handlers\exception.py", line 47, in inner
    response = get_response(request)
  File "E:\PycharmProjects\yyapi\venv\lib\site-packages\django\core\handlers\base.py", line 179, in _get_response
    response = wrapped_callback(request, *callback_args, **callback_kwargs)
  File "E:\PycharmProjects\yyapi\MyApp\views.py", line 928, in save_project_host
    DB_project_header.objects.create(project_id=project_id, name=names[i], host=hosts[i])
  File "E:\PycharmProjects\yyapi\venv\lib\site-packages\django\db\models\manager.py", line 85, in manager_method
    return getattr(self.get_queryset(), name)(*args, **kwargs)
  File "E:\PycharmProjects\yyapi\venv\lib\site-packages\django\db\models\query.py", line 445, in create
    obj = self.model(**kwargs)
  File "E:\PycharmProjects\yyapi\venv\lib\site-packages\django\db\models\base.py", line 501, in __init__
    raise TypeError("%s() got an unexpected keyword argument '%s'" % (cls.__name__, kwarg))
TypeError: DB_project_header() got an unexpected keyword argument 'host'
[2020-12-22 15:59:56,064][Thread-7:17156][task_id:django.request][log.py:230][ERROR][Internal Server Error: /save_project_host/]
Traceback (most recent call last):
  File "E:\PycharmProjects\yyapi\venv\lib\site-packages\django\core\handlers\exception.py", line 47, in inner
    response = get_response(request)
  File "E:\PycharmProjects\yyapi\venv\lib\site-packages\django\core\handlers\base.py", line 179, in _get_response
    response = wrapped_callback(request, *callback_args, **callback_kwargs)
  File "E:\PycharmProjects\yyapi\MyApp\views.py", line 928, in save_project_host
    DB_project_header.objects.create(project_id=project_id, name=names[i], host=hosts[i])
  File "E:\PycharmProjects\yyapi\venv\lib\site-packages\django\db\models\manager.py", line 85, in manager_method
    return getattr(self.get_queryset(), name)(*args, **kwargs)
  File "E:\PycharmProjects\yyapi\venv\lib\site-packages\django\db\models\query.py", line 445, in create
    obj = self.model(**kwargs)
  File "E:\PycharmProjects\yyapi\venv\lib\site-packages\django\db\models\base.py", line 501, in __init__
    raise TypeError("%s() got an unexpected keyword argument '%s'" % (cls.__name__, kwarg))
TypeError: DB_project_header() got an unexpected keyword argument 'host'
[2020-12-22 16:01:54,345][Thread-6:560][task_id:django.request][log.py:230][ERROR][Internal Server Error: /save_project_host/]
Traceback (most recent call last):
  File "E:\PycharmProjects\yyapi\venv\lib\site-packages\django\core\handlers\exception.py", line 47, in inner
    response = get_response(request)
  File "E:\PycharmProjects\yyapi\venv\lib\site-packages\django\core\handlers\base.py", line 179, in _get_response
    response = wrapped_callback(request, *callback_args, **callback_kwargs)
  File "E:\PycharmProjects\yyapi\MyApp\views.py", line 929, in save_project_host
    DB_project_header.objects.create(project_id=project_id, name=names[i], host=hosts[i])
  File "E:\PycharmProjects\yyapi\venv\lib\site-packages\django\db\models\manager.py", line 85, in manager_method
    return getattr(self.get_queryset(), name)(*args, **kwargs)
  File "E:\PycharmProjects\yyapi\venv\lib\site-packages\django\db\models\query.py", line 445, in create
    obj = self.model(**kwargs)
  File "E:\PycharmProjects\yyapi\venv\lib\site-packages\django\db\models\base.py", line 501, in __init__
    raise TypeError("%s() got an unexpected keyword argument '%s'" % (cls.__name__, kwarg))
TypeError: DB_project_header() got an unexpected keyword argument 'host'
[2020-12-22 16:33:13,110][Thread-6:14460][task_id:django.request][log.py:230][ERROR][Internal Server Error: /Api_send/]
Traceback (most recent call last):
  File "E:\PycharmProjects\yyapi\venv\lib\site-packages\django\db\models\fields\__init__.py", line 1774, in get_prep_value
    return int(value)
ValueError: invalid literal for int() with base 10: '搜狗'

The above exception was the direct cause of the following exception:

Traceback (most recent call last):
  File "E:\PycharmProjects\yyapi\venv\lib\site-packages\django\core\handlers\exception.py", line 47, in inner
    response = get_response(request)
  File "E:\PycharmProjects\yyapi\venv\lib\site-packages\django\core\handlers\base.py", line 179, in _get_response
    response = wrapped_callback(request, *callback_args, **callback_kwargs)
  File "E:\PycharmProjects\yyapi\MyApp\views.py", line 412, in Api_send
    ts_host = DB_project_host.objects.filter(id=prject_host_id)[0].host
  File "E:\PycharmProjects\yyapi\venv\lib\site-packages\django\db\models\manager.py", line 85, in manager_method
    return getattr(self.get_queryset(), name)(*args, **kwargs)
  File "E:\PycharmProjects\yyapi\venv\lib\site-packages\django\db\models\query.py", line 942, in filter
    return self._filter_or_exclude(False, *args, **kwargs)
  File "E:\PycharmProjects\yyapi\venv\lib\site-packages\django\db\models\query.py", line 962, in _filter_or_exclude
    clone._filter_or_exclude_inplace(negate, *args, **kwargs)
  File "E:\PycharmProjects\yyapi\venv\lib\site-packages\django\db\models\query.py", line 969, in _filter_or_exclude_inplace
    self._query.add_q(Q(*args, **kwargs))
  File "E:\PycharmProjects\yyapi\venv\lib\site-packages\django\db\models\sql\query.py", line 1358, in add_q
    clause, _ = self._add_q(q_object, self.used_aliases)
  File "E:\PycharmProjects\yyapi\venv\lib\site-packages\django\db\models\sql\query.py", line 1380, in _add_q
    split_subq=split_subq, check_filterable=check_filterable,
  File "E:\PycharmProjects\yyapi\venv\lib\site-packages\django\db\models\sql\query.py", line 1319, in build_filter
    condition = self.build_lookup(lookups, col, value)
  File "E:\PycharmProjects\yyapi\venv\lib\site-packages\django\db\models\sql\query.py", line 1165, in build_lookup
    lookup = lookup_class(lhs, rhs)
  File "E:\PycharmProjects\yyapi\venv\lib\site-packages\django\db\models\lookups.py", line 24, in __init__
    self.rhs = self.get_prep_lookup()
  File "E:\PycharmProjects\yyapi\venv\lib\site-packages\django\db\models\lookups.py", line 76, in get_prep_lookup
    return self.lhs.output_field.get_prep_value(self.rhs)
  File "E:\PycharmProjects\yyapi\venv\lib\site-packages\django\db\models\fields\__init__.py", line 1778, in get_prep_value
    ) from e
ValueError: Field 'id' expected a number but got '搜狗'.
[2020-12-22 16:33:49,605][Thread-9:10468][task_id:django.request][log.py:230][ERROR][Internal Server Error: /Api_send/]
Traceback (most recent call last):
  File "E:\PycharmProjects\yyapi\venv\lib\site-packages\django\db\models\fields\__init__.py", line 1774, in get_prep_value
    return int(value)
ValueError: invalid literal for int() with base 10: '百度'

The above exception was the direct cause of the following exception:

Traceback (most recent call last):
  File "E:\PycharmProjects\yyapi\venv\lib\site-packages\django\core\handlers\exception.py", line 47, in inner
    response = get_response(request)
  File "E:\PycharmProjects\yyapi\venv\lib\site-packages\django\core\handlers\base.py", line 179, in _get_response
    response = wrapped_callback(request, *callback_args, **callback_kwargs)
  File "E:\PycharmProjects\yyapi\MyApp\views.py", line 412, in Api_send
    ts_host = DB_project_host.objects.filter(id=prject_host_id)[0].host
  File "E:\PycharmProjects\yyapi\venv\lib\site-packages\django\db\models\manager.py", line 85, in manager_method
    return getattr(self.get_queryset(), name)(*args, **kwargs)
  File "E:\PycharmProjects\yyapi\venv\lib\site-packages\django\db\models\query.py", line 942, in filter
    return self._filter_or_exclude(False, *args, **kwargs)
  File "E:\PycharmProjects\yyapi\venv\lib\site-packages\django\db\models\query.py", line 962, in _filter_or_exclude
    clone._filter_or_exclude_inplace(negate, *args, **kwargs)
  File "E:\PycharmProjects\yyapi\venv\lib\site-packages\django\db\models\query.py", line 969, in _filter_or_exclude_inplace
    self._query.add_q(Q(*args, **kwargs))
  File "E:\PycharmProjects\yyapi\venv\lib\site-packages\django\db\models\sql\query.py", line 1358, in add_q
    clause, _ = self._add_q(q_object, self.used_aliases)
  File "E:\PycharmProjects\yyapi\venv\lib\site-packages\django\db\models\sql\query.py", line 1380, in _add_q
    split_subq=split_subq, check_filterable=check_filterable,
  File "E:\PycharmProjects\yyapi\venv\lib\site-packages\django\db\models\sql\query.py", line 1319, in build_filter
    condition = self.build_lookup(lookups, col, value)
  File "E:\PycharmProjects\yyapi\venv\lib\site-packages\django\db\models\sql\query.py", line 1165, in build_lookup
    lookup = lookup_class(lhs, rhs)
  File "E:\PycharmProjects\yyapi\venv\lib\site-packages\django\db\models\lookups.py", line 24, in __init__
    self.rhs = self.get_prep_lookup()
  File "E:\PycharmProjects\yyapi\venv\lib\site-packages\django\db\models\lookups.py", line 76, in get_prep_lookup
    return self.lhs.output_field.get_prep_value(self.rhs)
  File "E:\PycharmProjects\yyapi\venv\lib\site-packages\django\db\models\fields\__init__.py", line 1778, in get_prep_value
    ) from e
ValueError: Field 'id' expected a number but got '百度'.
[2020-12-22 16:34:03,206][Thread-9:10468][task_id:django.request][log.py:230][ERROR][Internal Server Error: /Api_send/]
Traceback (most recent call last):
  File "E:\PycharmProjects\yyapi\venv\lib\site-packages\django\db\models\fields\__init__.py", line 1774, in get_prep_value
    return int(value)
ValueError: invalid literal for int() with base 10: '百度'

The above exception was the direct cause of the following exception:

Traceback (most recent call last):
  File "E:\PycharmProjects\yyapi\venv\lib\site-packages\django\core\handlers\exception.py", line 47, in inner
    response = get_response(request)
  File "E:\PycharmProjects\yyapi\venv\lib\site-packages\django\core\handlers\base.py", line 179, in _get_response
    response = wrapped_callback(request, *callback_args, **callback_kwargs)
  File "E:\PycharmProjects\yyapi\MyApp\views.py", line 412, in Api_send
    ts_host = DB_project_host.objects.filter(id=prject_host_id)[0].host
  File "E:\PycharmProjects\yyapi\venv\lib\site-packages\django\db\models\manager.py", line 85, in manager_method
    return getattr(self.get_queryset(), name)(*args, **kwargs)
  File "E:\PycharmProjects\yyapi\venv\lib\site-packages\django\db\models\query.py", line 942, in filter
    return self._filter_or_exclude(False, *args, **kwargs)
  File "E:\PycharmProjects\yyapi\venv\lib\site-packages\django\db\models\query.py", line 962, in _filter_or_exclude
    clone._filter_or_exclude_inplace(negate, *args, **kwargs)
  File "E:\PycharmProjects\yyapi\venv\lib\site-packages\django\db\models\query.py", line 969, in _filter_or_exclude_inplace
    self._query.add_q(Q(*args, **kwargs))
  File "E:\PycharmProjects\yyapi\venv\lib\site-packages\django\db\models\sql\query.py", line 1358, in add_q
    clause, _ = self._add_q(q_object, self.used_aliases)
  File "E:\PycharmProjects\yyapi\venv\lib\site-packages\django\db\models\sql\query.py", line 1380, in _add_q
    split_subq=split_subq, check_filterable=check_filterable,
  File "E:\PycharmProjects\yyapi\venv\lib\site-packages\django\db\models\sql\query.py", line 1319, in build_filter
    condition = self.build_lookup(lookups, col, value)
  File "E:\PycharmProjects\yyapi\venv\lib\site-packages\django\db\models\sql\query.py", line 1165, in build_lookup
    lookup = lookup_class(lhs, rhs)
  File "E:\PycharmProjects\yyapi\venv\lib\site-packages\django\db\models\lookups.py", line 24, in __init__
    self.rhs = self.get_prep_lookup()
  File "E:\PycharmProjects\yyapi\venv\lib\site-packages\django\db\models\lookups.py", line 76, in get_prep_lookup
    return self.lhs.output_field.get_prep_value(self.rhs)
  File "E:\PycharmProjects\yyapi\venv\lib\site-packages\django\db\models\fields\__init__.py", line 1778, in get_prep_value
    ) from e
ValueError: Field 'id' expected a number but got '百度'.
[2020-12-22 16:34:04,894][Thread-9:10468][task_id:django.request][log.py:230][ERROR][Internal Server Error: /Api_send/]
Traceback (most recent call last):
  File "E:\PycharmProjects\yyapi\venv\lib\site-packages\django\db\models\fields\__init__.py", line 1774, in get_prep_value
    return int(value)
ValueError: invalid literal for int() with base 10: '百度'

The above exception was the direct cause of the following exception:

Traceback (most recent call last):
  File "E:\PycharmProjects\yyapi\venv\lib\site-packages\django\core\handlers\exception.py", line 47, in inner
    response = get_response(request)
  File "E:\PycharmProjects\yyapi\venv\lib\site-packages\django\core\handlers\base.py", line 179, in _get_response
    response = wrapped_callback(request, *callback_args, **callback_kwargs)
  File "E:\PycharmProjects\yyapi\MyApp\views.py", line 412, in Api_send
    ts_host = DB_project_host.objects.filter(id=prject_host_id)[0].host
  File "E:\PycharmProjects\yyapi\venv\lib\site-packages\django\db\models\manager.py", line 85, in manager_method
    return getattr(self.get_queryset(), name)(*args, **kwargs)
  File "E:\PycharmProjects\yyapi\venv\lib\site-packages\django\db\models\query.py", line 942, in filter
    return self._filter_or_exclude(False, *args, **kwargs)
  File "E:\PycharmProjects\yyapi\venv\lib\site-packages\django\db\models\query.py", line 962, in _filter_or_exclude
    clone._filter_or_exclude_inplace(negate, *args, **kwargs)
  File "E:\PycharmProjects\yyapi\venv\lib\site-packages\django\db\models\query.py", line 969, in _filter_or_exclude_inplace
    self._query.add_q(Q(*args, **kwargs))
  File "E:\PycharmProjects\yyapi\venv\lib\site-packages\django\db\models\sql\query.py", line 1358, in add_q
    clause, _ = self._add_q(q_object, self.used_aliases)
  File "E:\PycharmProjects\yyapi\venv\lib\site-packages\django\db\models\sql\query.py", line 1380, in _add_q
    split_subq=split_subq, check_filterable=check_filterable,
  File "E:\PycharmProjects\yyapi\venv\lib\site-packages\django\db\models\sql\query.py", line 1319, in build_filter
    condition = self.build_lookup(lookups, col, value)
  File "E:\PycharmProjects\yyapi\venv\lib\site-packages\django\db\models\sql\query.py", line 1165, in build_lookup
    lookup = lookup_class(lhs, rhs)
  File "E:\PycharmProjects\yyapi\venv\lib\site-packages\django\db\models\lookups.py", line 24, in __init__
    self.rhs = self.get_prep_lookup()
  File "E:\PycharmProjects\yyapi\venv\lib\site-packages\django\db\models\lookups.py", line 76, in get_prep_lookup
    return self.lhs.output_field.get_prep_value(self.rhs)
  File "E:\PycharmProjects\yyapi\venv\lib\site-packages\django\db\models\fields\__init__.py", line 1778, in get_prep_value
    ) from e
ValueError: Field 'id' expected a number but got '百度'.
[2020-12-22 16:34:47,171][Thread-9:10468][task_id:django.request][log.py:230][ERROR][Internal Server Error: /Api_send/]
Traceback (most recent call last):
  File "E:\PycharmProjects\yyapi\venv\lib\site-packages\django\db\models\fields\__init__.py", line 1774, in get_prep_value
    return int(value)
ValueError: invalid literal for int() with base 10: '百度'

The above exception was the direct cause of the following exception:

Traceback (most recent call last):
  File "E:\PycharmProjects\yyapi\venv\lib\site-packages\django\core\handlers\exception.py", line 47, in inner
    response = get_response(request)
  File "E:\PycharmProjects\yyapi\venv\lib\site-packages\django\core\handlers\base.py", line 179, in _get_response
    response = wrapped_callback(request, *callback_args, **callback_kwargs)
  File "E:\PycharmProjects\yyapi\MyApp\views.py", line 412, in Api_send
    ts_host = DB_project_host.objects.filter(id=prject_host_id)[0].host
  File "E:\PycharmProjects\yyapi\venv\lib\site-packages\django\db\models\manager.py", line 85, in manager_method
    return getattr(self.get_queryset(), name)(*args, **kwargs)
  File "E:\PycharmProjects\yyapi\venv\lib\site-packages\django\db\models\query.py", line 942, in filter
    return self._filter_or_exclude(False, *args, **kwargs)
  File "E:\PycharmProjects\yyapi\venv\lib\site-packages\django\db\models\query.py", line 962, in _filter_or_exclude
    clone._filter_or_exclude_inplace(negate, *args, **kwargs)
  File "E:\PycharmProjects\yyapi\venv\lib\site-packages\django\db\models\query.py", line 969, in _filter_or_exclude_inplace
    self._query.add_q(Q(*args, **kwargs))
  File "E:\PycharmProjects\yyapi\venv\lib\site-packages\django\db\models\sql\query.py", line 1358, in add_q
    clause, _ = self._add_q(q_object, self.used_aliases)
  File "E:\PycharmProjects\yyapi\venv\lib\site-packages\django\db\models\sql\query.py", line 1380, in _add_q
    split_subq=split_subq, check_filterable=check_filterable,
  File "E:\PycharmProjects\yyapi\venv\lib\site-packages\django\db\models\sql\query.py", line 1319, in build_filter
    condition = self.build_lookup(lookups, col, value)
  File "E:\PycharmProjects\yyapi\venv\lib\site-packages\django\db\models\sql\query.py", line 1165, in build_lookup
    lookup = lookup_class(lhs, rhs)
  File "E:\PycharmProjects\yyapi\venv\lib\site-packages\django\db\models\lookups.py", line 24, in __init__
    self.rhs = self.get_prep_lookup()
  File "E:\PycharmProjects\yyapi\venv\lib\site-packages\django\db\models\lookups.py", line 76, in get_prep_lookup
    return self.lhs.output_field.get_prep_value(self.rhs)
  File "E:\PycharmProjects\yyapi\venv\lib\site-packages\django\db\models\fields\__init__.py", line 1778, in get_prep_value
    ) from e
ValueError: Field 'id' expected a number but got '百度'.
[2020-12-22 16:38:33,353][Thread-11:16792][task_id:django.request][log.py:230][ERROR][Internal Server Error: /Api_send/]
Traceback (most recent call last):
  File "E:\PycharmProjects\yyapi\venv\lib\site-packages\django\db\models\fields\__init__.py", line 1774, in get_prep_value
    return int(value)
ValueError: invalid literal for int() with base 10: '百度'

The above exception was the direct cause of the following exception:

Traceback (most recent call last):
  File "E:\PycharmProjects\yyapi\venv\lib\site-packages\django\core\handlers\exception.py", line 47, in inner
    response = get_response(request)
  File "E:\PycharmProjects\yyapi\venv\lib\site-packages\django\core\handlers\base.py", line 179, in _get_response
    response = wrapped_callback(request, *callback_args, **callback_kwargs)
  File "E:\PycharmProjects\yyapi\MyApp\views.py", line 412, in Api_send
    ts_host = DB_project_host.objects.filter(id=prject_host_id)[0].host
  File "E:\PycharmProjects\yyapi\venv\lib\site-packages\django\db\models\manager.py", line 85, in manager_method
    return getattr(self.get_queryset(), name)(*args, **kwargs)
  File "E:\PycharmProjects\yyapi\venv\lib\site-packages\django\db\models\query.py", line 942, in filter
    return self._filter_or_exclude(False, *args, **kwargs)
  File "E:\PycharmProjects\yyapi\venv\lib\site-packages\django\db\models\query.py", line 962, in _filter_or_exclude
    clone._filter_or_exclude_inplace(negate, *args, **kwargs)
  File "E:\PycharmProjects\yyapi\venv\lib\site-packages\django\db\models\query.py", line 969, in _filter_or_exclude_inplace
    self._query.add_q(Q(*args, **kwargs))
  File "E:\PycharmProjects\yyapi\venv\lib\site-packages\django\db\models\sql\query.py", line 1358, in add_q
    clause, _ = self._add_q(q_object, self.used_aliases)
  File "E:\PycharmProjects\yyapi\venv\lib\site-packages\django\db\models\sql\query.py", line 1380, in _add_q
    split_subq=split_subq, check_filterable=check_filterable,
  File "E:\PycharmProjects\yyapi\venv\lib\site-packages\django\db\models\sql\query.py", line 1319, in build_filter
    condition = self.build_lookup(lookups, col, value)
  File "E:\PycharmProjects\yyapi\venv\lib\site-packages\django\db\models\sql\query.py", line 1165, in build_lookup
    lookup = lookup_class(lhs, rhs)
  File "E:\PycharmProjects\yyapi\venv\lib\site-packages\django\db\models\lookups.py", line 24, in __init__
    self.rhs = self.get_prep_lookup()
  File "E:\PycharmProjects\yyapi\venv\lib\site-packages\django\db\models\lookups.py", line 76, in get_prep_lookup
    return self.lhs.output_field.get_prep_value(self.rhs)
  File "E:\PycharmProjects\yyapi\venv\lib\site-packages\django\db\models\fields\__init__.py", line 1778, in get_prep_value
    ) from e
ValueError: Field 'id' expected a number but got '百度'.
[2020-12-22 16:51:44,259][Thread-6:1716][task_id:django.request][log.py:230][ERROR][Internal Server Error: /Api_send/]
Traceback (most recent call last):
  File "E:\PycharmProjects\yyapi\venv\lib\site-packages\django\utils\datastructures.py", line 76, in __getitem__
    list_ = super().__getitem__(key)
KeyError: 'ts_project_headers'

During handling of the above exception, another exception occurred:

Traceback (most recent call last):
  File "E:\PycharmProjects\yyapi\venv\lib\site-packages\django\core\handlers\exception.py", line 47, in inner
    response = get_response(request)
  File "E:\PycharmProjects\yyapi\venv\lib\site-packages\django\core\handlers\base.py", line 179, in _get_response
    response = wrapped_callback(request, *callback_args, **callback_kwargs)
  File "E:\PycharmProjects\yyapi\MyApp\views.py", line 408, in Api_send
    ts_project_headers = request.GET['ts_project_headers'].split(',') #获取公共请求头
  File "E:\PycharmProjects\yyapi\venv\lib\site-packages\django\utils\datastructures.py", line 78, in __getitem__
    raise MultiValueDictKeyError(key)
django.utils.datastructures.MultiValueDictKeyError: 'ts_project_headers'
[2020-12-22 16:51:53,762][Thread-6:1716][task_id:django.request][log.py:230][ERROR][Internal Server Error: /Api_send/]
Traceback (most recent call last):
  File "E:\PycharmProjects\yyapi\venv\lib\site-packages\django\utils\datastructures.py", line 76, in __getitem__
    list_ = super().__getitem__(key)
KeyError: 'ts_project_headers'

During handling of the above exception, another exception occurred:

Traceback (most recent call last):
  File "E:\PycharmProjects\yyapi\venv\lib\site-packages\django\core\handlers\exception.py", line 47, in inner
    response = get_response(request)
  File "E:\PycharmProjects\yyapi\venv\lib\site-packages\django\core\handlers\base.py", line 179, in _get_response
    response = wrapped_callback(request, *callback_args, **callback_kwargs)
  File "E:\PycharmProjects\yyapi\MyApp\views.py", line 408, in Api_send
    ts_project_headers = request.GET['ts_project_headers'].split(',') #获取公共请求头
  File "E:\PycharmProjects\yyapi\venv\lib\site-packages\django\utils\datastructures.py", line 78, in __getitem__
    raise MultiValueDictKeyError(key)
django.utils.datastructures.MultiValueDictKeyError: 'ts_project_headers'
[2020-12-22 16:52:08,530][Thread-6:1716][task_id:django.request][log.py:230][ERROR][Internal Server Error: /Api_send/]
Traceback (most recent call last):
  File "E:\PycharmProjects\yyapi\venv\lib\site-packages\django\utils\datastructures.py", line 76, in __getitem__
    list_ = super().__getitem__(key)
KeyError: 'ts_project_headers'

During handling of the above exception, another exception occurred:

Traceback (most recent call last):
  File "E:\PycharmProjects\yyapi\venv\lib\site-packages\django\core\handlers\exception.py", line 47, in inner
    response = get_response(request)
  File "E:\PycharmProjects\yyapi\venv\lib\site-packages\django\core\handlers\base.py", line 179, in _get_response
    response = wrapped_callback(request, *callback_args, **callback_kwargs)
  File "E:\PycharmProjects\yyapi\MyApp\views.py", line 408, in Api_send
    ts_project_headers = request.GET['ts_project_headers'].split(',') #获取公共请求头
  File "E:\PycharmProjects\yyapi\venv\lib\site-packages\django\utils\datastructures.py", line 78, in __getitem__
    raise MultiValueDictKeyError(key)
django.utils.datastructures.MultiValueDictKeyError: 'ts_project_headers'
[2020-12-30 14:57:56,528][Thread-10:13944][task_id:django.request][log.py:230][ERROR][Internal Server Error: /look_report/1/]
Traceback (most recent call last):
  File "E:\PycharmProjects\yyapi\venv\lib\site-packages\django\core\handlers\exception.py", line 47, in inner
    response = get_response(request)
  File "E:\PycharmProjects\yyapi\venv\lib\site-packages\django\core\handlers\base.py", line 179, in _get_response
    response = wrapped_callback(request, *callback_args, **callback_kwargs)
  File "E:\PycharmProjects\yyapi\MyApp\views.py", line 899, in look_report
    return render(request, 'Reports/%s.html'%Case_id)
  File "E:\PycharmProjects\yyapi\venv\lib\site-packages\django\shortcuts.py", line 19, in render
    content = loader.render_to_string(template_name, context, request, using=using)
  File "E:\PycharmProjects\yyapi\venv\lib\site-packages\django\template\loader.py", line 61, in render_to_string
    template = get_template(template_name, using=using)
  File "E:\PycharmProjects\yyapi\venv\lib\site-packages\django\template\loader.py", line 15, in get_template
    return engine.get_template(template_name)
  File "E:\PycharmProjects\yyapi\venv\lib\site-packages\django\template\backends\django.py", line 34, in get_template
    return Template(self.engine.get_template(template_name), self)
  File "E:\PycharmProjects\yyapi\venv\lib\site-packages\django\template\engine.py", line 143, in get_template
    template, origin = self.find_template(template_name)
  File "E:\PycharmProjects\yyapi\venv\lib\site-packages\django\template\engine.py", line 125, in find_template
    template = loader.get_template(name, skip=skip)
  File "E:\PycharmProjects\yyapi\venv\lib\site-packages\django\template\loaders\base.py", line 24, in get_template
    contents = self.get_contents(origin)
  File "E:\PycharmProjects\yyapi\venv\lib\site-packages\django\template\loaders\filesystem.py", line 24, in get_contents
    return fp.read()
  File "D:\Python\Python36\lib\codecs.py", line 321, in decode
    (result, consumed) = self._buffer_decode(data, self.errors, final)
UnicodeDecodeError: 'utf-8' codec can't decode byte 0x90 in position 15680: invalid start byte
[2020-12-30 15:22:45,129][Thread-6:7072][task_id:django.request][log.py:230][ERROR][Internal Server Error: /child/P_cases.html/1//]
Traceback (most recent call last):
  File "E:\PycharmProjects\yyapi\venv\lib\site-packages\django\core\handlers\exception.py", line 47, in inner
    response = get_response(request)
  File "E:\PycharmProjects\yyapi\venv\lib\site-packages\django\core\handlers\base.py", line 179, in _get_response
    response = wrapped_callback(request, *callback_args, **callback_kwargs)
  File "E:\PycharmProjects\yyapi\MyApp\views.py", line 70, in child
    res = child_json(eid, oid, ooid)
  File "E:\PycharmProjects\yyapi\MyApp\views.py", line 129, in child_json
    res = {"project":project,"Cases": Cases, "apis":apis,"project_header":project_hrader,'hosts':hosts,'project_host':project_host}
UnboundLocalError: local variable 'project_host' referenced before assignment
[2020-12-31 10:04:22,040][Thread-9:15780][task_id:django.request][log.py:230][ERROR][Internal Server Error: /Api_send_home/]
Traceback (most recent call last):
  File "E:\PycharmProjects\yyapi\venv\lib\site-packages\django\utils\datastructures.py", line 76, in __getitem__
    list_ = super().__getitem__(key)
KeyError: 'ts_api_body'

During handling of the above exception, another exception occurred:

Traceback (most recent call last):
  File "E:\PycharmProjects\yyapi\venv\lib\site-packages\django\core\handlers\exception.py", line 47, in inner
    response = get_response(request)
  File "E:\PycharmProjects\yyapi\venv\lib\site-packages\django\core\handlers\base.py", line 179, in _get_response
    response = wrapped_callback(request, *callback_args, **callback_kwargs)
  File "E:\PycharmProjects\yyapi\MyApp\views.py", line 632, in Api_send_home
    ts_api_body = request.GET['ts_api_body']
  File "E:\PycharmProjects\yyapi\venv\lib\site-packages\django\utils\datastructures.py", line 78, in __getitem__
    raise MultiValueDictKeyError(key)
django.utils.datastructures.MultiValueDictKeyError: 'ts_api_body'
[2020-12-31 10:04:27,812][Thread-9:15780][task_id:django.request][log.py:230][ERROR][Internal Server Error: /Api_send_home/]
Traceback (most recent call last):
  File "E:\PycharmProjects\yyapi\venv\lib\site-packages\django\utils\datastructures.py", line 76, in __getitem__
    list_ = super().__getitem__(key)
KeyError: 'ts_api_body'

During handling of the above exception, another exception occurred:

Traceback (most recent call last):
  File "E:\PycharmProjects\yyapi\venv\lib\site-packages\django\core\handlers\exception.py", line 47, in inner
    response = get_response(request)
  File "E:\PycharmProjects\yyapi\venv\lib\site-packages\django\core\handlers\base.py", line 179, in _get_response
    response = wrapped_callback(request, *callback_args, **callback_kwargs)
  File "E:\PycharmProjects\yyapi\MyApp\views.py", line 632, in Api_send_home
    ts_api_body = request.GET['ts_api_body']
  File "E:\PycharmProjects\yyapi\venv\lib\site-packages\django\utils\datastructures.py", line 78, in __getitem__
    raise MultiValueDictKeyError(key)
django.utils.datastructures.MultiValueDictKeyError: 'ts_api_body'
[2020-12-31 10:07:23,200][Thread-17:17180][task_id:django.request][log.py:230][ERROR][Internal Server Error: /Api_send_home/]
Traceback (most recent call last):
  File "E:\PycharmProjects\yyapi\venv\lib\site-packages\django\utils\datastructures.py", line 76, in __getitem__
    list_ = super().__getitem__(key)
KeyError: 'ts_api_body'

During handling of the above exception, another exception occurred:

Traceback (most recent call last):
  File "E:\PycharmProjects\yyapi\venv\lib\site-packages\django\core\handlers\exception.py", line 47, in inner
    response = get_response(request)
  File "E:\PycharmProjects\yyapi\venv\lib\site-packages\django\core\handlers\base.py", line 179, in _get_response
    response = wrapped_callback(request, *callback_args, **callback_kwargs)
  File "E:\PycharmProjects\yyapi\MyApp\views.py", line 632, in Api_send_home
    ts_api_body = request.GET['ts_api_body']
  File "E:\PycharmProjects\yyapi\venv\lib\site-packages\django\utils\datastructures.py", line 78, in __getitem__
    raise MultiValueDictKeyError(key)
django.utils.datastructures.MultiValueDictKeyError: 'ts_api_body'
[2020-12-31 10:07:34,876][Thread-17:17180][task_id:django.request][log.py:230][ERROR][Internal Server Error: /Api_send_home/]
Traceback (most recent call last):
  File "E:\PycharmProjects\yyapi\venv\lib\site-packages\django\utils\datastructures.py", line 76, in __getitem__
    list_ = super().__getitem__(key)
KeyError: 'ts_api_body'

During handling of the above exception, another exception occurred:

Traceback (most recent call last):
  File "E:\PycharmProjects\yyapi\venv\lib\site-packages\django\core\handlers\exception.py", line 47, in inner
    response = get_response(request)
  File "E:\PycharmProjects\yyapi\venv\lib\site-packages\django\core\handlers\base.py", line 179, in _get_response
    response = wrapped_callback(request, *callback_args, **callback_kwargs)
  File "E:\PycharmProjects\yyapi\MyApp\views.py", line 632, in Api_send_home
    ts_api_body = request.GET['ts_api_body']
  File "E:\PycharmProjects\yyapi\venv\lib\site-packages\django\utils\datastructures.py", line 78, in __getitem__
    raise MultiValueDictKeyError(key)
django.utils.datastructures.MultiValueDictKeyError: 'ts_api_body'
[2020-12-31 10:08:57,482][Thread-18:20152][task_id:django.request][log.py:230][ERROR][Internal Server Error: /Api_send_home/]
Traceback (most recent call last):
  File "E:\PycharmProjects\yyapi\venv\lib\site-packages\django\utils\datastructures.py", line 76, in __getitem__
    list_ = super().__getitem__(key)
KeyError: 'ts_api_body'

During handling of the above exception, another exception occurred:

Traceback (most recent call last):
  File "E:\PycharmProjects\yyapi\venv\lib\site-packages\django\core\handlers\exception.py", line 47, in inner
    response = get_response(request)
  File "E:\PycharmProjects\yyapi\venv\lib\site-packages\django\core\handlers\base.py", line 179, in _get_response
    response = wrapped_callback(request, *callback_args, **callback_kwargs)
  File "E:\PycharmProjects\yyapi\MyApp\views.py", line 632, in Api_send_home
    ts_api_body = request.GET['ts_api_body']
  File "E:\PycharmProjects\yyapi\venv\lib\site-packages\django\utils\datastructures.py", line 78, in __getitem__
    raise MultiValueDictKeyError(key)
django.utils.datastructures.MultiValueDictKeyError: 'ts_api_body'
[2020-12-31 10:08:58,015][Thread-18:20152][task_id:django.request][log.py:230][ERROR][Internal Server Error: /Api_send_home/]
Traceback (most recent call last):
  File "E:\PycharmProjects\yyapi\venv\lib\site-packages\django\utils\datastructures.py", line 76, in __getitem__
    list_ = super().__getitem__(key)
KeyError: 'ts_api_body'

During handling of the above exception, another exception occurred:

Traceback (most recent call last):
  File "E:\PycharmProjects\yyapi\venv\lib\site-packages\django\core\handlers\exception.py", line 47, in inner
    response = get_response(request)
  File "E:\PycharmProjects\yyapi\venv\lib\site-packages\django\core\handlers\base.py", line 179, in _get_response
    response = wrapped_callback(request, *callback_args, **callback_kwargs)
  File "E:\PycharmProjects\yyapi\MyApp\views.py", line 632, in Api_send_home
    ts_api_body = request.GET['ts_api_body']
  File "E:\PycharmProjects\yyapi\venv\lib\site-packages\django\utils\datastructures.py", line 78, in __getitem__
    raise MultiValueDictKeyError(key)
django.utils.datastructures.MultiValueDictKeyError: 'ts_api_body'
[2020-12-31 10:09:32,520][Thread-19:3036][task_id:django.request][log.py:230][ERROR][Internal Server Error: /Api_send_home/]
Traceback (most recent call last):
  File "E:\PycharmProjects\yyapi\venv\lib\site-packages\django\utils\datastructures.py", line 76, in __getitem__
    list_ = super().__getitem__(key)
KeyError: 'ts_api_body'

During handling of the above exception, another exception occurred:

Traceback (most recent call last):
  File "E:\PycharmProjects\yyapi\venv\lib\site-packages\django\core\handlers\exception.py", line 47, in inner
    response = get_response(request)
  File "E:\PycharmProjects\yyapi\venv\lib\site-packages\django\core\handlers\base.py", line 179, in _get_response
    response = wrapped_callback(request, *callback_args, **callback_kwargs)
  File "E:\PycharmProjects\yyapi\MyApp\views.py", line 632, in Api_send_home
    ts_api_body = request.GET['ts_api_body']
  File "E:\PycharmProjects\yyapi\venv\lib\site-packages\django\utils\datastructures.py", line 78, in __getitem__
    raise MultiValueDictKeyError(key)
django.utils.datastructures.MultiValueDictKeyError: 'ts_api_body'
[2020-12-31 10:10:25,766][Thread-19:3036][task_id:django.request][log.py:230][ERROR][Internal Server Error: /Api_send_home/]
Traceback (most recent call last):
  File "E:\PycharmProjects\yyapi\venv\lib\site-packages\django\utils\datastructures.py", line 76, in __getitem__
    list_ = super().__getitem__(key)
KeyError: 'ts_api_body'

During handling of the above exception, another exception occurred:

Traceback (most recent call last):
  File "E:\PycharmProjects\yyapi\venv\lib\site-packages\django\core\handlers\exception.py", line 47, in inner
    response = get_response(request)
  File "E:\PycharmProjects\yyapi\venv\lib\site-packages\django\core\handlers\base.py", line 179, in _get_response
    response = wrapped_callback(request, *callback_args, **callback_kwargs)
  File "E:\PycharmProjects\yyapi\MyApp\views.py", line 632, in Api_send_home
    ts_api_body = request.GET['ts_api_body']
  File "E:\PycharmProjects\yyapi\venv\lib\site-packages\django\utils\datastructures.py", line 78, in __getitem__
    raise MultiValueDictKeyError(key)
django.utils.datastructures.MultiValueDictKeyError: 'ts_api_body'
[2020-12-31 10:22:51,407][Thread-6:18112][task_id:django.request][log.py:230][ERROR][Internal Server Error: /Api_send_home/]
Traceback (most recent call last):
  File "E:\PycharmProjects\yyapi\venv\lib\site-packages\django\utils\datastructures.py", line 76, in __getitem__
    list_ = super().__getitem__(key)
KeyError: 'ts_api_body'

During handling of the above exception, another exception occurred:

Traceback (most recent call last):
  File "E:\PycharmProjects\yyapi\venv\lib\site-packages\django\core\handlers\exception.py", line 47, in inner
    response = get_response(request)
  File "E:\PycharmProjects\yyapi\venv\lib\site-packages\django\core\handlers\base.py", line 179, in _get_response
    response = wrapped_callback(request, *callback_args, **callback_kwargs)
  File "E:\PycharmProjects\yyapi\MyApp\views.py", line 632, in Api_send_home
    ts_api_body = request.GET['ts_api_body']
  File "E:\PycharmProjects\yyapi\venv\lib\site-packages\django\utils\datastructures.py", line 78, in __getitem__
    raise MultiValueDictKeyError(key)
django.utils.datastructures.MultiValueDictKeyError: 'ts_api_body'
[2020-12-31 10:22:52,339][Thread-6:18112][task_id:django.request][log.py:230][ERROR][Internal Server Error: /Api_send_home/]
Traceback (most recent call last):
  File "E:\PycharmProjects\yyapi\venv\lib\site-packages\django\utils\datastructures.py", line 76, in __getitem__
    list_ = super().__getitem__(key)
KeyError: 'ts_api_body'

During handling of the above exception, another exception occurred:

Traceback (most recent call last):
  File "E:\PycharmProjects\yyapi\venv\lib\site-packages\django\core\handlers\exception.py", line 47, in inner
    response = get_response(request)
  File "E:\PycharmProjects\yyapi\venv\lib\site-packages\django\core\handlers\base.py", line 179, in _get_response
    response = wrapped_callback(request, *callback_args, **callback_kwargs)
  File "E:\PycharmProjects\yyapi\MyApp\views.py", line 632, in Api_send_home
    ts_api_body = request.GET['ts_api_body']
  File "E:\PycharmProjects\yyapi\venv\lib\site-packages\django\utils\datastructures.py", line 78, in __getitem__
    raise MultiValueDictKeyError(key)
django.utils.datastructures.MultiValueDictKeyError: 'ts_api_body'
[2020-12-31 10:22:52,885][Thread-6:18112][task_id:django.request][log.py:230][ERROR][Internal Server Error: /Api_send_home/]
Traceback (most recent call last):
  File "E:\PycharmProjects\yyapi\venv\lib\site-packages\django\utils\datastructures.py", line 76, in __getitem__
    list_ = super().__getitem__(key)
KeyError: 'ts_api_body'

During handling of the above exception, another exception occurred:

Traceback (most recent call last):
  File "E:\PycharmProjects\yyapi\venv\lib\site-packages\django\core\handlers\exception.py", line 47, in inner
    response = get_response(request)
  File "E:\PycharmProjects\yyapi\venv\lib\site-packages\django\core\handlers\base.py", line 179, in _get_response
    response = wrapped_callback(request, *callback_args, **callback_kwargs)
  File "E:\PycharmProjects\yyapi\MyApp\views.py", line 632, in Api_send_home
    ts_api_body = request.GET['ts_api_body']
  File "E:\PycharmProjects\yyapi\venv\lib\site-packages\django\utils\datastructures.py", line 78, in __getitem__
    raise MultiValueDictKeyError(key)
django.utils.datastructures.MultiValueDictKeyError: 'ts_api_body'
[2020-12-31 10:22:53,133][Thread-6:18112][task_id:django.request][log.py:230][ERROR][Internal Server Error: /Api_send_home/]
Traceback (most recent call last):
  File "E:\PycharmProjects\yyapi\venv\lib\site-packages\django\utils\datastructures.py", line 76, in __getitem__
    list_ = super().__getitem__(key)
KeyError: 'ts_api_body'

During handling of the above exception, another exception occurred:

Traceback (most recent call last):
  File "E:\PycharmProjects\yyapi\venv\lib\site-packages\django\core\handlers\exception.py", line 47, in inner
    response = get_response(request)
  File "E:\PycharmProjects\yyapi\venv\lib\site-packages\django\core\handlers\base.py", line 179, in _get_response
    response = wrapped_callback(request, *callback_args, **callback_kwargs)
  File "E:\PycharmProjects\yyapi\MyApp\views.py", line 632, in Api_send_home
    ts_api_body = request.GET['ts_api_body']
  File "E:\PycharmProjects\yyapi\venv\lib\site-packages\django\utils\datastructures.py", line 78, in __getitem__
    raise MultiValueDictKeyError(key)
django.utils.datastructures.MultiValueDictKeyError: 'ts_api_body'
[2020-12-31 10:22:53,335][Thread-6:18112][task_id:django.request][log.py:230][ERROR][Internal Server Error: /Api_send_home/]
Traceback (most recent call last):
  File "E:\PycharmProjects\yyapi\venv\lib\site-packages\django\utils\datastructures.py", line 76, in __getitem__
    list_ = super().__getitem__(key)
KeyError: 'ts_api_body'

During handling of the above exception, another exception occurred:

Traceback (most recent call last):
  File "E:\PycharmProjects\yyapi\venv\lib\site-packages\django\core\handlers\exception.py", line 47, in inner
    response = get_response(request)
  File "E:\PycharmProjects\yyapi\venv\lib\site-packages\django\core\handlers\base.py", line 179, in _get_response
    response = wrapped_callback(request, *callback_args, **callback_kwargs)
  File "E:\PycharmProjects\yyapi\MyApp\views.py", line 632, in Api_send_home
    ts_api_body = request.GET['ts_api_body']
  File "E:\PycharmProjects\yyapi\venv\lib\site-packages\django\utils\datastructures.py", line 78, in __getitem__
    raise MultiValueDictKeyError(key)
django.utils.datastructures.MultiValueDictKeyError: 'ts_api_body'
[2020-12-31 10:23:33,911][Thread-6:19232][task_id:django.request][log.py:230][ERROR][Internal Server Error: /Api_send_home/]
Traceback (most recent call last):
  File "E:\PycharmProjects\yyapi\venv\lib\site-packages\django\utils\datastructures.py", line 76, in __getitem__
    list_ = super().__getitem__(key)
KeyError: 'ts_api_body'

During handling of the above exception, another exception occurred:

Traceback (most recent call last):
  File "E:\PycharmProjects\yyapi\venv\lib\site-packages\django\core\handlers\exception.py", line 47, in inner
    response = get_response(request)
  File "E:\PycharmProjects\yyapi\venv\lib\site-packages\django\core\handlers\base.py", line 179, in _get_response
    response = wrapped_callback(request, *callback_args, **callback_kwargs)
  File "E:\PycharmProjects\yyapi\MyApp\views.py", line 632, in Api_send_home
    ts_api_body = request.GET['ts_api_body']
  File "E:\PycharmProjects\yyapi\venv\lib\site-packages\django\utils\datastructures.py", line 78, in __getitem__
    raise MultiValueDictKeyError(key)
django.utils.datastructures.MultiValueDictKeyError: 'ts_api_body'
[2020-12-31 10:23:35,191][Thread-6:19232][task_id:django.request][log.py:230][ERROR][Internal Server Error: /Api_send_home/]
Traceback (most recent call last):
  File "E:\PycharmProjects\yyapi\venv\lib\site-packages\django\utils\datastructures.py", line 76, in __getitem__
    list_ = super().__getitem__(key)
KeyError: 'ts_api_body'

During handling of the above exception, another exception occurred:

Traceback (most recent call last):
  File "E:\PycharmProjects\yyapi\venv\lib\site-packages\django\core\handlers\exception.py", line 47, in inner
    response = get_response(request)
  File "E:\PycharmProjects\yyapi\venv\lib\site-packages\django\core\handlers\base.py", line 179, in _get_response
    response = wrapped_callback(request, *callback_args, **callback_kwargs)
  File "E:\PycharmProjects\yyapi\MyApp\views.py", line 632, in Api_send_home
    ts_api_body = request.GET['ts_api_body']
  File "E:\PycharmProjects\yyapi\venv\lib\site-packages\django\utils\datastructures.py", line 78, in __getitem__
    raise MultiValueDictKeyError(key)
django.utils.datastructures.MultiValueDictKeyError: 'ts_api_body'
[2020-12-31 10:23:35,415][Thread-6:19232][task_id:django.request][log.py:230][ERROR][Internal Server Error: /Api_send_home/]
Traceback (most recent call last):
  File "E:\PycharmProjects\yyapi\venv\lib\site-packages\django\utils\datastructures.py", line 76, in __getitem__
    list_ = super().__getitem__(key)
KeyError: 'ts_api_body'

During handling of the above exception, another exception occurred:

Traceback (most recent call last):
  File "E:\PycharmProjects\yyapi\venv\lib\site-packages\django\core\handlers\exception.py", line 47, in inner
    response = get_response(request)
  File "E:\PycharmProjects\yyapi\venv\lib\site-packages\django\core\handlers\base.py", line 179, in _get_response
    response = wrapped_callback(request, *callback_args, **callback_kwargs)
  File "E:\PycharmProjects\yyapi\MyApp\views.py", line 632, in Api_send_home
    ts_api_body = request.GET['ts_api_body']
  File "E:\PycharmProjects\yyapi\venv\lib\site-packages\django\utils\datastructures.py", line 78, in __getitem__
    raise MultiValueDictKeyError(key)
django.utils.datastructures.MultiValueDictKeyError: 'ts_api_body'
[2020-12-31 10:25:18,052][Thread-14:20336][task_id:django.request][log.py:230][ERROR][Internal Server Error: /Api_send/]
Traceback (most recent call last):
  File "E:\PycharmProjects\yyapi\venv\lib\site-packages\django\db\models\fields\__init__.py", line 1774, in get_prep_value
    return int(value)
ValueError: invalid literal for int() with base 10: ''

The above exception was the direct cause of the following exception:

Traceback (most recent call last):
  File "E:\PycharmProjects\yyapi\venv\lib\site-packages\django\core\handlers\exception.py", line 47, in inner
    response = get_response(request)
  File "E:\PycharmProjects\yyapi\venv\lib\site-packages\django\core\handlers\base.py", line 179, in _get_response
    response = wrapped_callback(request, *callback_args, **callback_kwargs)
  File "E:\PycharmProjects\yyapi\MyApp\views.py", line 433, in Api_send
    project_header = DB_project_header.objects.filter(id=i)[0]
  File "E:\PycharmProjects\yyapi\venv\lib\site-packages\django\db\models\manager.py", line 85, in manager_method
    return getattr(self.get_queryset(), name)(*args, **kwargs)
  File "E:\PycharmProjects\yyapi\venv\lib\site-packages\django\db\models\query.py", line 942, in filter
    return self._filter_or_exclude(False, *args, **kwargs)
  File "E:\PycharmProjects\yyapi\venv\lib\site-packages\django\db\models\query.py", line 962, in _filter_or_exclude
    clone._filter_or_exclude_inplace(negate, *args, **kwargs)
  File "E:\PycharmProjects\yyapi\venv\lib\site-packages\django\db\models\query.py", line 969, in _filter_or_exclude_inplace
    self._query.add_q(Q(*args, **kwargs))
  File "E:\PycharmProjects\yyapi\venv\lib\site-packages\django\db\models\sql\query.py", line 1358, in add_q
    clause, _ = self._add_q(q_object, self.used_aliases)
  File "E:\PycharmProjects\yyapi\venv\lib\site-packages\django\db\models\sql\query.py", line 1380, in _add_q
    split_subq=split_subq, check_filterable=check_filterable,
  File "E:\PycharmProjects\yyapi\venv\lib\site-packages\django\db\models\sql\query.py", line 1319, in build_filter
    condition = self.build_lookup(lookups, col, value)
  File "E:\PycharmProjects\yyapi\venv\lib\site-packages\django\db\models\sql\query.py", line 1165, in build_lookup
    lookup = lookup_class(lhs, rhs)
  File "E:\PycharmProjects\yyapi\venv\lib\site-packages\django\db\models\lookups.py", line 24, in __init__
    self.rhs = self.get_prep_lookup()
  File "E:\PycharmProjects\yyapi\venv\lib\site-packages\django\db\models\lookups.py", line 76, in get_prep_lookup
    return self.lhs.output_field.get_prep_value(self.rhs)
  File "E:\PycharmProjects\yyapi\venv\lib\site-packages\django\db\models\fields\__init__.py", line 1778, in get_prep_value
    ) from e
ValueError: Field 'id' expected a number but got ''.
[2020-12-31 10:25:26,653][Thread-14:20336][task_id:django.request][log.py:230][ERROR][Internal Server Error: /Api_send/]
Traceback (most recent call last):
  File "E:\PycharmProjects\yyapi\venv\lib\site-packages\django\db\models\fields\__init__.py", line 1774, in get_prep_value
    return int(value)
ValueError: invalid literal for int() with base 10: ''

The above exception was the direct cause of the following exception:

Traceback (most recent call last):
  File "E:\PycharmProjects\yyapi\venv\lib\site-packages\django\core\handlers\exception.py", line 47, in inner
    response = get_response(request)
  File "E:\PycharmProjects\yyapi\venv\lib\site-packages\django\core\handlers\base.py", line 179, in _get_response
    response = wrapped_callback(request, *callback_args, **callback_kwargs)
  File "E:\PycharmProjects\yyapi\MyApp\views.py", line 433, in Api_send
    project_header = DB_project_header.objects.filter(id=i)[0]
  File "E:\PycharmProjects\yyapi\venv\lib\site-packages\django\db\models\manager.py", line 85, in manager_method
    return getattr(self.get_queryset(), name)(*args, **kwargs)
  File "E:\PycharmProjects\yyapi\venv\lib\site-packages\django\db\models\query.py", line 942, in filter
    return self._filter_or_exclude(False, *args, **kwargs)
  File "E:\PycharmProjects\yyapi\venv\lib\site-packages\django\db\models\query.py", line 962, in _filter_or_exclude
    clone._filter_or_exclude_inplace(negate, *args, **kwargs)
  File "E:\PycharmProjects\yyapi\venv\lib\site-packages\django\db\models\query.py", line 969, in _filter_or_exclude_inplace
    self._query.add_q(Q(*args, **kwargs))
  File "E:\PycharmProjects\yyapi\venv\lib\site-packages\django\db\models\sql\query.py", line 1358, in add_q
    clause, _ = self._add_q(q_object, self.used_aliases)
  File "E:\PycharmProjects\yyapi\venv\lib\site-packages\django\db\models\sql\query.py", line 1380, in _add_q
    split_subq=split_subq, check_filterable=check_filterable,
  File "E:\PycharmProjects\yyapi\venv\lib\site-packages\django\db\models\sql\query.py", line 1319, in build_filter
    condition = self.build_lookup(lookups, col, value)
  File "E:\PycharmProjects\yyapi\venv\lib\site-packages\django\db\models\sql\query.py", line 1165, in build_lookup
    lookup = lookup_class(lhs, rhs)
  File "E:\PycharmProjects\yyapi\venv\lib\site-packages\django\db\models\lookups.py", line 24, in __init__
    self.rhs = self.get_prep_lookup()
  File "E:\PycharmProjects\yyapi\venv\lib\site-packages\django\db\models\lookups.py", line 76, in get_prep_lookup
    return self.lhs.output_field.get_prep_value(self.rhs)
  File "E:\PycharmProjects\yyapi\venv\lib\site-packages\django\db\models\fields\__init__.py", line 1778, in get_prep_value
    ) from e
ValueError: Field 'id' expected a number but got ''.
[2020-12-31 10:25:40,806][Thread-14:20336][task_id:django.request][log.py:230][ERROR][Internal Server Error: /Api_send/]
Traceback (most recent call last):
  File "E:\PycharmProjects\yyapi\venv\lib\site-packages\django\db\models\fields\__init__.py", line 1774, in get_prep_value
    return int(value)
ValueError: invalid literal for int() with base 10: ''

The above exception was the direct cause of the following exception:

Traceback (most recent call last):
  File "E:\PycharmProjects\yyapi\venv\lib\site-packages\django\core\handlers\exception.py", line 47, in inner
    response = get_response(request)
  File "E:\PycharmProjects\yyapi\venv\lib\site-packages\django\core\handlers\base.py", line 179, in _get_response
    response = wrapped_callback(request, *callback_args, **callback_kwargs)
  File "E:\PycharmProjects\yyapi\MyApp\views.py", line 433, in Api_send
    project_header = DB_project_header.objects.filter(id=i)[0]
  File "E:\PycharmProjects\yyapi\venv\lib\site-packages\django\db\models\manager.py", line 85, in manager_method
    return getattr(self.get_queryset(), name)(*args, **kwargs)
  File "E:\PycharmProjects\yyapi\venv\lib\site-packages\django\db\models\query.py", line 942, in filter
    return self._filter_or_exclude(False, *args, **kwargs)
  File "E:\PycharmProjects\yyapi\venv\lib\site-packages\django\db\models\query.py", line 962, in _filter_or_exclude
    clone._filter_or_exclude_inplace(negate, *args, **kwargs)
  File "E:\PycharmProjects\yyapi\venv\lib\site-packages\django\db\models\query.py", line 969, in _filter_or_exclude_inplace
    self._query.add_q(Q(*args, **kwargs))
  File "E:\PycharmProjects\yyapi\venv\lib\site-packages\django\db\models\sql\query.py", line 1358, in add_q
    clause, _ = self._add_q(q_object, self.used_aliases)
  File "E:\PycharmProjects\yyapi\venv\lib\site-packages\django\db\models\sql\query.py", line 1380, in _add_q
    split_subq=split_subq, check_filterable=check_filterable,
  File "E:\PycharmProjects\yyapi\venv\lib\site-packages\django\db\models\sql\query.py", line 1319, in build_filter
    condition = self.build_lookup(lookups, col, value)
  File "E:\PycharmProjects\yyapi\venv\lib\site-packages\django\db\models\sql\query.py", line 1165, in build_lookup
    lookup = lookup_class(lhs, rhs)
  File "E:\PycharmProjects\yyapi\venv\lib\site-packages\django\db\models\lookups.py", line 24, in __init__
    self.rhs = self.get_prep_lookup()
  File "E:\PycharmProjects\yyapi\venv\lib\site-packages\django\db\models\lookups.py", line 76, in get_prep_lookup
    return self.lhs.output_field.get_prep_value(self.rhs)
  File "E:\PycharmProjects\yyapi\venv\lib\site-packages\django\db\models\fields\__init__.py", line 1778, in get_prep_value
    ) from e
ValueError: Field 'id' expected a number but got ''.
[2020-12-31 10:33:45,762][Thread-19:14872][task_id:django.request][log.py:230][ERROR][Internal Server Error: /Api_send/]
Traceback (most recent call last):
  File "E:\PycharmProjects\yyapi\venv\lib\site-packages\django\db\models\fields\__init__.py", line 1774, in get_prep_value
    return int(value)
ValueError: invalid literal for int() with base 10: ''

The above exception was the direct cause of the following exception:

Traceback (most recent call last):
  File "E:\PycharmProjects\yyapi\venv\lib\site-packages\django\core\handlers\exception.py", line 47, in inner
    response = get_response(request)
  File "E:\PycharmProjects\yyapi\venv\lib\site-packages\django\core\handlers\base.py", line 179, in _get_response
    response = wrapped_callback(request, *callback_args, **callback_kwargs)
  File "E:\PycharmProjects\yyapi\MyApp\views.py", line 433, in Api_send
    project_header = DB_project_header.objects.filter(id=i)[0]
  File "E:\PycharmProjects\yyapi\venv\lib\site-packages\django\db\models\manager.py", line 85, in manager_method
    return getattr(self.get_queryset(), name)(*args, **kwargs)
  File "E:\PycharmProjects\yyapi\venv\lib\site-packages\django\db\models\query.py", line 942, in filter
    return self._filter_or_exclude(False, *args, **kwargs)
  File "E:\PycharmProjects\yyapi\venv\lib\site-packages\django\db\models\query.py", line 962, in _filter_or_exclude
    clone._filter_or_exclude_inplace(negate, *args, **kwargs)
  File "E:\PycharmProjects\yyapi\venv\lib\site-packages\django\db\models\query.py", line 969, in _filter_or_exclude_inplace
    self._query.add_q(Q(*args, **kwargs))
  File "E:\PycharmProjects\yyapi\venv\lib\site-packages\django\db\models\sql\query.py", line 1358, in add_q
    clause, _ = self._add_q(q_object, self.used_aliases)
  File "E:\PycharmProjects\yyapi\venv\lib\site-packages\django\db\models\sql\query.py", line 1380, in _add_q
    split_subq=split_subq, check_filterable=check_filterable,
  File "E:\PycharmProjects\yyapi\venv\lib\site-packages\django\db\models\sql\query.py", line 1319, in build_filter
    condition = self.build_lookup(lookups, col, value)
  File "E:\PycharmProjects\yyapi\venv\lib\site-packages\django\db\models\sql\query.py", line 1165, in build_lookup
    lookup = lookup_class(lhs, rhs)
  File "E:\PycharmProjects\yyapi\venv\lib\site-packages\django\db\models\lookups.py", line 24, in __init__
    self.rhs = self.get_prep_lookup()
  File "E:\PycharmProjects\yyapi\venv\lib\site-packages\django\db\models\lookups.py", line 76, in get_prep_lookup
    return self.lhs.output_field.get_prep_value(self.rhs)
  File "E:\PycharmProjects\yyapi\venv\lib\site-packages\django\db\models\fields\__init__.py", line 1778, in get_prep_value
    ) from e
ValueError: Field 'id' expected a number but got ''.
[2020-12-31 10:37:22,020][Thread-23:652][task_id:django.request][log.py:230][ERROR][Internal Server Error: /Api_send/]
Traceback (most recent call last):
  File "E:\PycharmProjects\yyapi\venv\lib\site-packages\django\db\models\fields\__init__.py", line 1774, in get_prep_value
    return int(value)
ValueError: invalid literal for int() with base 10: ''

The above exception was the direct cause of the following exception:

Traceback (most recent call last):
  File "E:\PycharmProjects\yyapi\venv\lib\site-packages\django\core\handlers\exception.py", line 47, in inner
    response = get_response(request)
  File "E:\PycharmProjects\yyapi\venv\lib\site-packages\django\core\handlers\base.py", line 179, in _get_response
    response = wrapped_callback(request, *callback_args, **callback_kwargs)
  File "E:\PycharmProjects\yyapi\MyApp\views.py", line 433, in Api_send
    project_header = DB_project_header.objects.filter(id=i)[0]
  File "E:\PycharmProjects\yyapi\venv\lib\site-packages\django\db\models\manager.py", line 85, in manager_method
    return getattr(self.get_queryset(), name)(*args, **kwargs)
  File "E:\PycharmProjects\yyapi\venv\lib\site-packages\django\db\models\query.py", line 942, in filter
    return self._filter_or_exclude(False, *args, **kwargs)
  File "E:\PycharmProjects\yyapi\venv\lib\site-packages\django\db\models\query.py", line 962, in _filter_or_exclude
    clone._filter_or_exclude_inplace(negate, *args, **kwargs)
  File "E:\PycharmProjects\yyapi\venv\lib\site-packages\django\db\models\query.py", line 969, in _filter_or_exclude_inplace
    self._query.add_q(Q(*args, **kwargs))
  File "E:\PycharmProjects\yyapi\venv\lib\site-packages\django\db\models\sql\query.py", line 1358, in add_q
    clause, _ = self._add_q(q_object, self.used_aliases)
  File "E:\PycharmProjects\yyapi\venv\lib\site-packages\django\db\models\sql\query.py", line 1380, in _add_q
    split_subq=split_subq, check_filterable=check_filterable,
  File "E:\PycharmProjects\yyapi\venv\lib\site-packages\django\db\models\sql\query.py", line 1319, in build_filter
    condition = self.build_lookup(lookups, col, value)
  File "E:\PycharmProjects\yyapi\venv\lib\site-packages\django\db\models\sql\query.py", line 1165, in build_lookup
    lookup = lookup_class(lhs, rhs)
  File "E:\PycharmProjects\yyapi\venv\lib\site-packages\django\db\models\lookups.py", line 24, in __init__
    self.rhs = self.get_prep_lookup()
  File "E:\PycharmProjects\yyapi\venv\lib\site-packages\django\db\models\lookups.py", line 76, in get_prep_lookup
    return self.lhs.output_field.get_prep_value(self.rhs)
  File "E:\PycharmProjects\yyapi\venv\lib\site-packages\django\db\models\fields\__init__.py", line 1778, in get_prep_value
    ) from e
ValueError: Field 'id' expected a number but got ''.
[2020-12-31 10:41:22,959][Thread-25:16616][task_id:django.request][log.py:230][ERROR][Internal Server Error: /Api_send/]
Traceback (most recent call last):
  File "E:\PycharmProjects\yyapi\venv\lib\site-packages\django\db\models\fields\__init__.py", line 1774, in get_prep_value
    return int(value)
ValueError: invalid literal for int() with base 10: ''

The above exception was the direct cause of the following exception:

Traceback (most recent call last):
  File "E:\PycharmProjects\yyapi\venv\lib\site-packages\django\core\handlers\exception.py", line 47, in inner
    response = get_response(request)
  File "E:\PycharmProjects\yyapi\venv\lib\site-packages\django\core\handlers\base.py", line 179, in _get_response
    response = wrapped_callback(request, *callback_args, **callback_kwargs)
  File "E:\PycharmProjects\yyapi\MyApp\views.py", line 433, in Api_send
    project_header = DB_project_header.objects.filter(id=i)[0]
  File "E:\PycharmProjects\yyapi\venv\lib\site-packages\django\db\models\manager.py", line 85, in manager_method
    return getattr(self.get_queryset(), name)(*args, **kwargs)
  File "E:\PycharmProjects\yyapi\venv\lib\site-packages\django\db\models\query.py", line 942, in filter
    return self._filter_or_exclude(False, *args, **kwargs)
  File "E:\PycharmProjects\yyapi\venv\lib\site-packages\django\db\models\query.py", line 962, in _filter_or_exclude
    clone._filter_or_exclude_inplace(negate, *args, **kwargs)
  File "E:\PycharmProjects\yyapi\venv\lib\site-packages\django\db\models\query.py", line 969, in _filter_or_exclude_inplace
    self._query.add_q(Q(*args, **kwargs))
  File "E:\PycharmProjects\yyapi\venv\lib\site-packages\django\db\models\sql\query.py", line 1358, in add_q
    clause, _ = self._add_q(q_object, self.used_aliases)
  File "E:\PycharmProjects\yyapi\venv\lib\site-packages\django\db\models\sql\query.py", line 1380, in _add_q
    split_subq=split_subq, check_filterable=check_filterable,
  File "E:\PycharmProjects\yyapi\venv\lib\site-packages\django\db\models\sql\query.py", line 1319, in build_filter
    condition = self.build_lookup(lookups, col, value)
  File "E:\PycharmProjects\yyapi\venv\lib\site-packages\django\db\models\sql\query.py", line 1165, in build_lookup
    lookup = lookup_class(lhs, rhs)
  File "E:\PycharmProjects\yyapi\venv\lib\site-packages\django\db\models\lookups.py", line 24, in __init__
    self.rhs = self.get_prep_lookup()
  File "E:\PycharmProjects\yyapi\venv\lib\site-packages\django\db\models\lookups.py", line 76, in get_prep_lookup
    return self.lhs.output_field.get_prep_value(self.rhs)
  File "E:\PycharmProjects\yyapi\venv\lib\site-packages\django\db\models\fields\__init__.py", line 1778, in get_prep_value
    ) from e
ValueError: Field 'id' expected a number but got ''.
[2020-12-31 10:41:44,400][Thread-25:16616][task_id:django.request][log.py:230][ERROR][Internal Server Error: /Api_send/]
Traceback (most recent call last):
  File "E:\PycharmProjects\yyapi\venv\lib\site-packages\django\db\models\fields\__init__.py", line 1774, in get_prep_value
    return int(value)
ValueError: invalid literal for int() with base 10: ''

The above exception was the direct cause of the following exception:

Traceback (most recent call last):
  File "E:\PycharmProjects\yyapi\venv\lib\site-packages\django\core\handlers\exception.py", line 47, in inner
    response = get_response(request)
  File "E:\PycharmProjects\yyapi\venv\lib\site-packages\django\core\handlers\base.py", line 179, in _get_response
    response = wrapped_callback(request, *callback_args, **callback_kwargs)
  File "E:\PycharmProjects\yyapi\MyApp\views.py", line 433, in Api_send
    project_header = DB_project_header.objects.filter(id=i)[0]
  File "E:\PycharmProjects\yyapi\venv\lib\site-packages\django\db\models\manager.py", line 85, in manager_method
    return getattr(self.get_queryset(), name)(*args, **kwargs)
  File "E:\PycharmProjects\yyapi\venv\lib\site-packages\django\db\models\query.py", line 942, in filter
    return self._filter_or_exclude(False, *args, **kwargs)
  File "E:\PycharmProjects\yyapi\venv\lib\site-packages\django\db\models\query.py", line 962, in _filter_or_exclude
    clone._filter_or_exclude_inplace(negate, *args, **kwargs)
  File "E:\PycharmProjects\yyapi\venv\lib\site-packages\django\db\models\query.py", line 969, in _filter_or_exclude_inplace
    self._query.add_q(Q(*args, **kwargs))
  File "E:\PycharmProjects\yyapi\venv\lib\site-packages\django\db\models\sql\query.py", line 1358, in add_q
    clause, _ = self._add_q(q_object, self.used_aliases)
  File "E:\PycharmProjects\yyapi\venv\lib\site-packages\django\db\models\sql\query.py", line 1380, in _add_q
    split_subq=split_subq, check_filterable=check_filterable,
  File "E:\PycharmProjects\yyapi\venv\lib\site-packages\django\db\models\sql\query.py", line 1319, in build_filter
    condition = self.build_lookup(lookups, col, value)
  File "E:\PycharmProjects\yyapi\venv\lib\site-packages\django\db\models\sql\query.py", line 1165, in build_lookup
    lookup = lookup_class(lhs, rhs)
  File "E:\PycharmProjects\yyapi\venv\lib\site-packages\django\db\models\lookups.py", line 24, in __init__
    self.rhs = self.get_prep_lookup()
  File "E:\PycharmProjects\yyapi\venv\lib\site-packages\django\db\models\lookups.py", line 76, in get_prep_lookup
    return self.lhs.output_field.get_prep_value(self.rhs)
  File "E:\PycharmProjects\yyapi\venv\lib\site-packages\django\db\models\fields\__init__.py", line 1778, in get_prep_value
    ) from e
ValueError: Field 'id' expected a number but got ''.
[2021-01-25 11:15:56,809][Thread-6:10036][task_id:django.request][log.py:230][ERROR][Internal Server Error: /project_get_login/]
Traceback (most recent call last):
  File "E:\PycharmProjects\yyapi\venv\lib\site-packages\django\core\handlers\exception.py", line 47, in inner
    response = get_response(request)
  File "E:\PycharmProjects\yyapi\venv\lib\site-packages\django\core\handlers\base.py", line 179, in _get_response
    response = wrapped_callback(request, *callback_args, **callback_kwargs)
  File "E:\PycharmProjects\yyapi\MyApp\views.py", line 980, in project_get_login
    return HttpResponse(json.dumps(login),content_type='application/json')
  File "D:\Python\Python36\lib\json\__init__.py", line 231, in dumps
    return _default_encoder.encode(obj)
  File "D:\Python\Python36\lib\json\encoder.py", line 199, in encode
    chunks = self.iterencode(o, _one_shot=True)
  File "D:\Python\Python36\lib\json\encoder.py", line 257, in iterencode
    return _iterencode(o, 0)
  File "D:\Python\Python36\lib\json\encoder.py", line 180, in default
    o.__class__.__name__)
TypeError: Object of type 'QuerySet' is not JSON serializable
[2021-01-25 11:16:39,350][Thread-8:11652][task_id:django.request][log.py:230][ERROR][Internal Server Error: /project_get_login/]
Traceback (most recent call last):
  File "E:\PycharmProjects\yyapi\venv\lib\site-packages\django\core\handlers\exception.py", line 47, in inner
    response = get_response(request)
  File "E:\PycharmProjects\yyapi\venv\lib\site-packages\django\core\handlers\base.py", line 179, in _get_response
    response = wrapped_callback(request, *callback_args, **callback_kwargs)
  File "E:\PycharmProjects\yyapi\MyApp\views.py", line 980, in project_get_login
    return HttpResponse(json.dumps(login),content_type='application/json')
  File "D:\Python\Python36\lib\json\__init__.py", line 231, in dumps
    return _default_encoder.encode(obj)
  File "D:\Python\Python36\lib\json\encoder.py", line 199, in encode
    chunks = self.iterencode(o, _one_shot=True)
  File "D:\Python\Python36\lib\json\encoder.py", line 257, in iterencode
    return _iterencode(o, 0)
  File "D:\Python\Python36\lib\json\encoder.py", line 180, in default
    o.__class__.__name__)
TypeError: Object of type 'QuerySet' is not JSON serializable
[2021-02-02 10:59:48,434][Thread-6:12808][task_id:django.request][log.py:230][ERROR][Internal Server Error: /zhengjiao_play/]
Traceback (most recent call last):
  File "E:\PycharmProjects\yyapi\venv\lib\site-packages\django\core\handlers\exception.py", line 47, in inner
    response = get_response(request)
  File "E:\PycharmProjects\yyapi\venv\lib\site-packages\django\core\handlers\base.py", line 179, in _get_response
    response = wrapped_callback(request, *callback_args, **callback_kwargs)
  File "E:\PycharmProjects\yyapi\MyApp\views_tools.py", line 31, in zhengjiao_play
    for i in AllPairs(new_values):
  File "E:\PycharmProjects\yyapi\venv\lib\site-packages\allpairspy\allpairs.py", line 61, in __init__
    self.__validate_parameter(parameters)
  File "E:\PycharmProjects\yyapi\venv\lib\site-packages\allpairspy\allpairs.py", line 170, in __validate_parameter
    raise ValueError("must provide more than one option")
ValueError: must provide more than one option
[2021-02-02 15:08:13,954][Thread-6:10304][task_id:django.request][log.py:230][ERROR][Internal Server Error: /bianjie_play/]
Traceback (most recent call last):
  File "E:\PycharmProjects\yyapi\venv\lib\site-packages\django\core\handlers\exception.py", line 47, in inner
    response = get_response(request)
  File "E:\PycharmProjects\yyapi\venv\lib\site-packages\django\core\handlers\base.py", line 179, in _get_response
    response = wrapped_callback(request, *callback_args, **callback_kwargs)
  File "E:\PycharmProjects\yyapi\MyApp\views_tools.py", line 119, in bianjie_play
    for i in range(min):
TypeError: 'str' object cannot be interpreted as an integer
[2021-02-02 15:09:12,511][Thread-6:13352][task_id:django.request][log.py:230][ERROR][Internal Server Error: /bianjie_play/]
Traceback (most recent call last):
  File "E:\PycharmProjects\yyapi\venv\lib\site-packages\django\core\handlers\exception.py", line 47, in inner
    response = get_response(request)
  File "E:\PycharmProjects\yyapi\venv\lib\site-packages\django\core\handlers\base.py", line 179, in _get_response
    response = wrapped_callback(request, *callback_args, **callback_kwargs)
  File "E:\PycharmProjects\yyapi\MyApp\views_tools.py", line 119, in bianjie_play
    for i in range(int(min)):
ValueError: invalid literal for int() with base 10: '[object NodeList]'
[2021-02-02 15:20:55,751][Thread-16:3852][task_id:django.request][log.py:230][ERROR][Internal Server Error: /bianjie_play/]
Traceback (most recent call last):
  File "E:\PycharmProjects\yyapi\venv\lib\site-packages\django\utils\datastructures.py", line 76, in __getitem__
    list_ = super().__getitem__(key)
KeyError: 'min'

During handling of the above exception, another exception occurred:

Traceback (most recent call last):
  File "E:\PycharmProjects\yyapi\venv\lib\site-packages\django\core\handlers\exception.py", line 47, in inner
    response = get_response(request)
  File "E:\PycharmProjects\yyapi\venv\lib\site-packages\django\core\handlers\base.py", line 179, in _get_response
    response = wrapped_callback(request, *callback_args, **callback_kwargs)
  File "E:\PycharmProjects\yyapi\MyApp\views_tools.py", line 115, in bianjie_play
    min = request.GET['min']
  File "E:\PycharmProjects\yyapi\venv\lib\site-packages\django\utils\datastructures.py", line 78, in __getitem__
    raise MultiValueDictKeyError(key)
django.utils.datastructures.MultiValueDictKeyError: 'min'
[2021-02-02 15:21:52,533][Thread-21:11396][task_id:django.request][log.py:230][ERROR][Internal Server Error: /bianjie_play/]
Traceback (most recent call last):
  File "E:\PycharmProjects\yyapi\venv\lib\site-packages\django\utils\datastructures.py", line 76, in __getitem__
    list_ = super().__getitem__(key)
KeyError: 'min'

During handling of the above exception, another exception occurred:

Traceback (most recent call last):
  File "E:\PycharmProjects\yyapi\venv\lib\site-packages\django\core\handlers\exception.py", line 47, in inner
    response = get_response(request)
  File "E:\PycharmProjects\yyapi\venv\lib\site-packages\django\core\handlers\base.py", line 179, in _get_response
    response = wrapped_callback(request, *callback_args, **callback_kwargs)
  File "E:\PycharmProjects\yyapi\MyApp\views_tools.py", line 115, in bianjie_play
    min = request.GET['min']
  File "E:\PycharmProjects\yyapi\venv\lib\site-packages\django\utils\datastructures.py", line 78, in __getitem__
    raise MultiValueDictKeyError(key)
django.utils.datastructures.MultiValueDictKeyError: 'min'
[2021-02-02 15:29:20,727][Thread-31:12168][task_id:django.request][log.py:230][ERROR][Internal Server Error: /bianjie_play/]
Traceback (most recent call last):
  File "E:\PycharmProjects\yyapi\venv\lib\site-packages\django\utils\datastructures.py", line 76, in __getitem__
    list_ = super().__getitem__(key)
KeyError: 'min'

During handling of the above exception, another exception occurred:

Traceback (most recent call last):
  File "E:\PycharmProjects\yyapi\venv\lib\site-packages\django\core\handlers\exception.py", line 47, in inner
    response = get_response(request)
  File "E:\PycharmProjects\yyapi\venv\lib\site-packages\django\core\handlers\base.py", line 179, in _get_response
    response = wrapped_callback(request, *callback_args, **callback_kwargs)
  File "E:\PycharmProjects\yyapi\MyApp\views_tools.py", line 115, in bianjie_play
    min = request.GET['min']
  File "E:\PycharmProjects\yyapi\venv\lib\site-packages\django\utils\datastructures.py", line 78, in __getitem__
    raise MultiValueDictKeyError(key)
django.utils.datastructures.MultiValueDictKeyError: 'min'
[2021-02-02 15:30:05,968][Thread-6:15460][task_id:django.request][log.py:230][ERROR][Internal Server Error: /bianjie_play/]
Traceback (most recent call last):
  File "E:\PycharmProjects\yyapi\venv\lib\site-packages\django\utils\datastructures.py", line 76, in __getitem__
    list_ = super().__getitem__(key)
KeyError: 'min_zn'

During handling of the above exception, another exception occurred:

Traceback (most recent call last):
  File "E:\PycharmProjects\yyapi\venv\lib\site-packages\django\core\handlers\exception.py", line 47, in inner
    response = get_response(request)
  File "E:\PycharmProjects\yyapi\venv\lib\site-packages\django\core\handlers\base.py", line 179, in _get_response
    response = wrapped_callback(request, *callback_args, **callback_kwargs)
  File "E:\PycharmProjects\yyapi\MyApp\views_tools.py", line 115, in bianjie_play
    min_zn = request.GET['min_zn']
  File "E:\PycharmProjects\yyapi\venv\lib\site-packages\django\utils\datastructures.py", line 78, in __getitem__
    raise MultiValueDictKeyError(key)
django.utils.datastructures.MultiValueDictKeyError: 'min_zn'
[2021-02-02 15:37:38,286][Thread-17:17300][task_id:django.request][log.py:230][ERROR][Internal Server Error: /zhengjiao_play/]
Traceback (most recent call last):
  File "E:\PycharmProjects\yyapi\venv\lib\site-packages\django\core\handlers\exception.py", line 47, in inner
    response = get_response(request)
  File "E:\PycharmProjects\yyapi\venv\lib\site-packages\django\core\handlers\base.py", line 179, in _get_response
    response = wrapped_callback(request, *callback_args, **callback_kwargs)
  File "E:\PycharmProjects\yyapi\MyApp\views_tools.py", line 37, in zhengjiao_play
    for i in AllPairs(new_values):
  File "E:\PycharmProjects\yyapi\venv\lib\site-packages\allpairspy\allpairs.py", line 61, in __init__
    self.__validate_parameter(parameters)
  File "E:\PycharmProjects\yyapi\venv\lib\site-packages\allpairspy\allpairs.py", line 170, in __validate_parameter
    raise ValueError("must provide more than one option")
ValueError: must provide more than one option
[2021-02-02 15:41:52,882][Thread-18:16260][task_id:django.request][log.py:230][ERROR][Internal Server Error: /bianjie_play/]
Traceback (most recent call last):
  File "E:\PycharmProjects\yyapi\venv\lib\site-packages\django\utils\datastructures.py", line 76, in __getitem__
    list_ = super().__getitem__(key)
KeyError: 'min_zn'

During handling of the above exception, another exception occurred:

Traceback (most recent call last):
  File "E:\PycharmProjects\yyapi\venv\lib\site-packages\django\core\handlers\exception.py", line 47, in inner
    response = get_response(request)
  File "E:\PycharmProjects\yyapi\venv\lib\site-packages\django\core\handlers\base.py", line 179, in _get_response
    response = wrapped_callback(request, *callback_args, **callback_kwargs)
  File "E:\PycharmProjects\yyapi\MyApp\views_tools.py", line 115, in bianjie_play
    min_zn = request.GET['min_zn']
  File "E:\PycharmProjects\yyapi\venv\lib\site-packages\django\utils\datastructures.py", line 78, in __getitem__
    raise MultiValueDictKeyError(key)
django.utils.datastructures.MultiValueDictKeyError: 'min_zn'
[2021-02-02 15:43:08,311][Thread-18:16260][task_id:django.request][log.py:230][ERROR][Internal Server Error: /bianjie_play/]
Traceback (most recent call last):
  File "E:\PycharmProjects\yyapi\venv\lib\site-packages\django\core\handlers\exception.py", line 47, in inner
    response = get_response(request)
  File "E:\PycharmProjects\yyapi\venv\lib\site-packages\django\core\handlers\base.py", line 179, in _get_response
    response = wrapped_callback(request, *callback_args, **callback_kwargs)
  File "E:\PycharmProjects\yyapi\MyApp\views_tools.py", line 119, in bianjie_play
    for i in range(min_zn):
TypeError: 'str' object cannot be interpreted as an integer
[2021-02-02 15:43:33,595][Thread-24:17336][task_id:django.request][log.py:230][ERROR][Internal Server Error: /bianjie_play/]
Traceback (most recent call last):
  File "E:\PycharmProjects\yyapi\venv\lib\site-packages\django\core\handlers\exception.py", line 47, in inner
    response = get_response(request)
  File "E:\PycharmProjects\yyapi\venv\lib\site-packages\django\core\handlers\base.py", line 179, in _get_response
    response = wrapped_callback(request, *callback_args, **callback_kwargs)
  File "E:\PycharmProjects\yyapi\MyApp\views_tools.py", line 119, in bianjie_play
    for i in range(min_zn):
TypeError: 'str' object cannot be interpreted as an integer
[2021-02-02 15:54:45,118][Thread-17:2096][task_id:django.request][log.py:230][ERROR][Internal Server Error: /bianjie_play/]
Traceback (most recent call last):
  File "E:\PycharmProjects\yyapi\venv\lib\site-packages\django\core\handlers\exception.py", line 47, in inner
    response = get_response(request)
  File "E:\PycharmProjects\yyapi\venv\lib\site-packages\django\core\handlers\base.py", line 179, in _get_response
    response = wrapped_callback(request, *callback_args, **callback_kwargs)
  File "E:\PycharmProjects\yyapi\MyApp\views_tools.py", line 119, in bianjie_play
    for i in range(int(max_zn)):
ValueError: invalid literal for int() with base 10: ''
[2021-02-02 15:56:09,812][Thread-22:16928][task_id:django.request][log.py:230][ERROR][Internal Server Error: /bianjie_play/]
Traceback (most recent call last):
  File "E:\PycharmProjects\yyapi\venv\lib\site-packages\django\core\handlers\exception.py", line 47, in inner
    response = get_response(request)
  File "E:\PycharmProjects\yyapi\venv\lib\site-packages\django\core\handlers\base.py", line 179, in _get_response
    response = wrapped_callback(request, *callback_args, **callback_kwargs)
  File "E:\PycharmProjects\yyapi\MyApp\views_tools.py", line 123, in bianjie_play
    str = bytes.fromhex(val).decode('gb2312')
UnicodeDecodeError: 'gb2312' codec can't decode byte 0xd7 in position 0: illegal multibyte sequence
[2021-02-05 16:09:39,785][Thread-6:10576][task_id:django.request][log.py:230][ERROR][Internal Server Error: /bianjie_play/]
Traceback (most recent call last):
  File "E:\PycharmProjects\yyapi\venv\lib\site-packages\qrcode\image\pil.py", line 6, in <module>
    from PIL import Image, ImageDraw
ModuleNotFoundError: No module named 'PIL'

During handling of the above exception, another exception occurred:

Traceback (most recent call last):
  File "E:\PycharmProjects\yyapi\venv\lib\site-packages\django\core\handlers\exception.py", line 47, in inner
    response = get_response(request)
  File "E:\PycharmProjects\yyapi\venv\lib\site-packages\django\core\handlers\base.py", line 179, in _get_response
    response = wrapped_callback(request, *callback_args, **callback_kwargs)
  File "E:\PycharmProjects\yyapi\MyApp\views_tools.py", line 134, in bianjie_play
    data_zn_img = qr.make_image(fill_color="black", back_color="white")
  File "E:\PycharmProjects\yyapi\venv\lib\site-packages\qrcode\main.py", line 289, in make_image
    from qrcode.image.pil import PilImage
  File "E:\PycharmProjects\yyapi\venv\lib\site-packages\qrcode\image\pil.py", line 8, in <module>
    import Image
ModuleNotFoundError: No module named 'Image'
[2021-02-05 16:09:40,466][Thread-6:10576][task_id:django.request][log.py:230][ERROR][Internal Server Error: /bianjie_play/]
Traceback (most recent call last):
  File "E:\PycharmProjects\yyapi\venv\lib\site-packages\qrcode\image\pil.py", line 6, in <module>
    from PIL import Image, ImageDraw
ModuleNotFoundError: No module named 'PIL'

During handling of the above exception, another exception occurred:

Traceback (most recent call last):
  File "E:\PycharmProjects\yyapi\venv\lib\site-packages\django\core\handlers\exception.py", line 47, in inner
    response = get_response(request)
  File "E:\PycharmProjects\yyapi\venv\lib\site-packages\django\core\handlers\base.py", line 179, in _get_response
    response = wrapped_callback(request, *callback_args, **callback_kwargs)
  File "E:\PycharmProjects\yyapi\MyApp\views_tools.py", line 134, in bianjie_play
    data_zn_img = qr.make_image(fill_color="black", back_color="white")
  File "E:\PycharmProjects\yyapi\venv\lib\site-packages\qrcode\main.py", line 289, in make_image
    from qrcode.image.pil import PilImage
  File "E:\PycharmProjects\yyapi\venv\lib\site-packages\qrcode\image\pil.py", line 8, in <module>
    import Image
ModuleNotFoundError: No module named 'Image'
[2021-02-05 16:30:18,731][Thread-14:4068][task_id:django.request][log.py:230][ERROR][Internal Server Error: /bianjie_play/]
Traceback (most recent call last):
  File "E:\PycharmProjects\yyapi\venv\lib\site-packages\django\core\handlers\exception.py", line 47, in inner
    response = get_response(request)
  File "E:\PycharmProjects\yyapi\venv\lib\site-packages\django\core\handlers\base.py", line 179, in _get_response
    response = wrapped_callback(request, *callback_args, **callback_kwargs)
  File "E:\PycharmProjects\yyapi\MyApp\views_tools.py", line 117, in bianjie_play
    for i in range(int(max_zn)):
ValueError: invalid literal for int() with base 10: ''
[2021-02-05 16:44:48,630][Thread-62:14296][task_id:django.request][log.py:230][ERROR][Internal Server Error: /bianjie_play/]
Traceback (most recent call last):
  File "E:\PycharmProjects\yyapi\venv\lib\site-packages\django\core\handlers\exception.py", line 47, in inner
    response = get_response(request)
  File "E:\PycharmProjects\yyapi\venv\lib\site-packages\django\core\handlers\base.py", line 179, in _get_response
    response = wrapped_callback(request, *callback_args, **callback_kwargs)
  File "E:\PycharmProjects\yyapi\MyApp\views_tools.py", line 117, in bianjie_play
    for i in range(int(max_zn)):
ValueError: invalid literal for int() with base 10: ''
[2021-02-05 17:17:59,345][Thread-23:14256][task_id:django.request][log.py:230][ERROR][Internal Server Error: /bianjie_play/]
Traceback (most recent call last):
  File "E:\PycharmProjects\yyapi\venv\lib\site-packages\django\core\handlers\exception.py", line 47, in inner
    response = get_response(request)
  File "E:\PycharmProjects\yyapi\venv\lib\site-packages\django\core\handlers\base.py", line 179, in _get_response
    response = wrapped_callback(request, *callback_args, **callback_kwargs)
  File "E:\PycharmProjects\yyapi\MyApp\views_tools.py", line 121, in bianjie_play
    str = bytes.fromhex(val).decode('gb2312')
UnicodeDecodeError: 'gb2312' codec can't decode byte 0xd7 in position 0: illegal multibyte sequence
[2021-02-05 17:23:17,944][Thread-6:7560][task_id:django.request][log.py:230][ERROR][Internal Server Error: /bianjie_play/]
Traceback (most recent call last):
  File "E:\PycharmProjects\yyapi\venv\lib\site-packages\django\core\handlers\exception.py", line 47, in inner
    response = get_response(request)
  File "E:\PycharmProjects\yyapi\venv\lib\site-packages\django\core\handlers\base.py", line 179, in _get_response
    response = wrapped_callback(request, *callback_args, **callback_kwargs)
  File "E:\PycharmProjects\yyapi\MyApp\views_tools.py", line 115, in bianjie_play
    os.remove('static/zn_img.png')
FileNotFoundError: [WinError 2] 系统找不到指定的文件。: 'static/zn_img.png'
[2021-02-05 17:23:22,336][Thread-6:7560][task_id:django.request][log.py:230][ERROR][Internal Server Error: /bianjie_play/]
Traceback (most recent call last):
  File "E:\PycharmProjects\yyapi\venv\lib\site-packages\django\core\handlers\exception.py", line 47, in inner
    response = get_response(request)
  File "E:\PycharmProjects\yyapi\venv\lib\site-packages\django\core\handlers\base.py", line 179, in _get_response
    response = wrapped_callback(request, *callback_args, **callback_kwargs)
  File "E:\PycharmProjects\yyapi\MyApp\views_tools.py", line 115, in bianjie_play
    os.remove('static/zn_img.png')
FileNotFoundError: [WinError 2] 系统找不到指定的文件。: 'static/zn_img.png'
[2021-02-05 17:25:22,114][Thread-6:3608][task_id:django.request][log.py:230][ERROR][Internal Server Error: /bianjie_play/]
Traceback (most recent call last):
  File "E:\PycharmProjects\yyapi\venv\lib\site-packages\django\core\handlers\exception.py", line 47, in inner
    response = get_response(request)
  File "E:\PycharmProjects\yyapi\venv\lib\site-packages\django\core\handlers\base.py", line 179, in _get_response
    response = wrapped_callback(request, *callback_args, **callback_kwargs)
  File "E:\PycharmProjects\yyapi\MyApp\views_tools.py", line 116, in bianjie_play
    os.remove('static/zn_img.png')
FileNotFoundError: [WinError 2] 系统找不到指定的文件。: 'static/zn_img.png'
[2021-02-05 17:25:36,611][Thread-6:3608][task_id:django.request][log.py:230][ERROR][Internal Server Error: /bianjie_play/]
Traceback (most recent call last):
  File "E:\PycharmProjects\yyapi\venv\lib\site-packages\django\core\handlers\exception.py", line 47, in inner
    response = get_response(request)
  File "E:\PycharmProjects\yyapi\venv\lib\site-packages\django\core\handlers\base.py", line 179, in _get_response
    response = wrapped_callback(request, *callback_args, **callback_kwargs)
  File "E:\PycharmProjects\yyapi\MyApp\views_tools.py", line 116, in bianjie_play
    os.remove('static/zn_img.png')
FileNotFoundError: [WinError 2] 系统找不到指定的文件。: 'static/zn_img.png'
[2021-02-05 17:55:02,865][Thread-18:16468][task_id:django.request][log.py:230][ERROR][Internal Server Error: /bianjie_play/]
Traceback (most recent call last):
  File "E:\PycharmProjects\yyapi\venv\lib\site-packages\django\core\handlers\exception.py", line 47, in inner
    response = get_response(request)
  File "E:\PycharmProjects\yyapi\venv\lib\site-packages\django\core\handlers\base.py", line 179, in _get_response
    response = wrapped_callback(request, *callback_args, **callback_kwargs)
  File "E:\PycharmProjects\yyapi\MyApp\views_tools.py", line 122, in bianjie_play
    str = bytes.fromhex(val).decode('gb2312')
UnicodeDecodeError: 'gb2312' codec can't decode byte 0xd7 in position 0: illegal multibyte sequence
[2021-02-05 17:55:19,416][Thread-19:6940][task_id:django.request][log.py:230][ERROR][Internal Server Error: /bianjie_play/]
Traceback (most recent call last):
  File "E:\PycharmProjects\yyapi\venv\lib\site-packages\django\core\handlers\exception.py", line 47, in inner
    response = get_response(request)
  File "E:\PycharmProjects\yyapi\venv\lib\site-packages\django\core\handlers\base.py", line 179, in _get_response
    response = wrapped_callback(request, *callback_args, **callback_kwargs)
  File "E:\PycharmProjects\yyapi\MyApp\views_tools.py", line 122, in bianjie_play
    str = bytes.fromhex(val).decode('gb2312')
UnicodeDecodeError: 'gb2312' codec can't decode byte 0xd7 in position 0: illegal multibyte sequence
[2021-02-22 10:13:16,548][Thread-11:3384][task_id:django.request][log.py:230][ERROR][Internal Server Error: /bianjie_play/]
Traceback (most recent call last):
  File "E:\PycharmProjects\yyapi\venv\lib\site-packages\django\core\handlers\exception.py", line 47, in inner
    response = get_response(request)
  File "E:\PycharmProjects\yyapi\venv\lib\site-packages\django\core\handlers\base.py", line 179, in _get_response
    response = wrapped_callback(request, *callback_args, **callback_kwargs)
  File "E:\PycharmProjects\yyapi\MyApp\views_tools.py", line 146, in bianjie_play
    qr_2.add_data(res_2)
UnboundLocalError: local variable 'res_2' referenced before assignment
[2021-06-18 10:13:00,988][Thread-3:8020][task_id:django.request][log.py:230][ERROR][Internal Server Error: /zhengjiao_play/]
Traceback (most recent call last):
  File "E:\PycharmProjects\yyapi\venv\lib\site-packages\django\core\handlers\exception.py", line 47, in inner
    response = get_response(request)
  File "E:\PycharmProjects\yyapi\venv\lib\site-packages\django\core\handlers\base.py", line 179, in _get_response
    response = wrapped_callback(request, *callback_args, **callback_kwargs)
  File "E:\PycharmProjects\yyapi\MyApp\views_tools.py", line 38, in zhengjiao_play
    for i in AllPairs(new_values):
  File "E:\PycharmProjects\yyapi\venv\lib\site-packages\allpairspy\allpairs.py", line 61, in __init__
    self.__validate_parameter(parameters)
  File "E:\PycharmProjects\yyapi\venv\lib\site-packages\allpairspy\allpairs.py", line 170, in __validate_parameter
    raise ValueError("must provide more than one option")
ValueError: must provide more than one option
[2021-06-18 10:13:02,938][Thread-3:8020][task_id:django.request][log.py:230][ERROR][Internal Server Error: /zhengjiao_play/]
Traceback (most recent call last):
  File "E:\PycharmProjects\yyapi\venv\lib\site-packages\django\core\handlers\exception.py", line 47, in inner
    response = get_response(request)
  File "E:\PycharmProjects\yyapi\venv\lib\site-packages\django\core\handlers\base.py", line 179, in _get_response
    response = wrapped_callback(request, *callback_args, **callback_kwargs)
  File "E:\PycharmProjects\yyapi\MyApp\views_tools.py", line 38, in zhengjiao_play
    for i in AllPairs(new_values):
  File "E:\PycharmProjects\yyapi\venv\lib\site-packages\allpairspy\allpairs.py", line 61, in __init__
    self.__validate_parameter(parameters)
  File "E:\PycharmProjects\yyapi\venv\lib\site-packages\allpairspy\allpairs.py", line 170, in __validate_parameter
    raise ValueError("must provide more than one option")
ValueError: must provide more than one option
[2021-08-17 14:21:23,469][Thread-2:10840][task_id:django.request][log.py:230][ERROR][Internal Server Error: /global_data_save/]
Traceback (most recent call last):
  File "E:\PycharmProjects\yyapi\venv\lib\site-packages\django\db\models\fields\__init__.py", line 1774, in get_prep_value
    return int(value)
ValueError: invalid literal for int() with base 10: ''

The above exception was the direct cause of the following exception:

Traceback (most recent call last):
  File "E:\PycharmProjects\yyapi\venv\lib\site-packages\django\core\handlers\exception.py", line 47, in inner
    response = get_response(request)
  File "E:\PycharmProjects\yyapi\venv\lib\site-packages\django\core\handlers\base.py", line 179, in _get_response
    response = wrapped_callback(request, *callback_args, **callback_kwargs)
  File "E:\PycharmProjects\yyapi\MyApp\views.py", line 1453, in global_data_save
    DB_global_data.objects.filter(id=global_id).update(name=global_name,data=global_data)
  File "E:\PycharmProjects\yyapi\venv\lib\site-packages\django\db\models\manager.py", line 85, in manager_method
    return getattr(self.get_queryset(), name)(*args, **kwargs)
  File "E:\PycharmProjects\yyapi\venv\lib\site-packages\django\db\models\query.py", line 942, in filter
    return self._filter_or_exclude(False, *args, **kwargs)
  File "E:\PycharmProjects\yyapi\venv\lib\site-packages\django\db\models\query.py", line 962, in _filter_or_exclude
    clone._filter_or_exclude_inplace(negate, *args, **kwargs)
  File "E:\PycharmProjects\yyapi\venv\lib\site-packages\django\db\models\query.py", line 969, in _filter_or_exclude_inplace
    self._query.add_q(Q(*args, **kwargs))
  File "E:\PycharmProjects\yyapi\venv\lib\site-packages\django\db\models\sql\query.py", line 1358, in add_q
    clause, _ = self._add_q(q_object, self.used_aliases)
  File "E:\PycharmProjects\yyapi\venv\lib\site-packages\django\db\models\sql\query.py", line 1380, in _add_q
    split_subq=split_subq, check_filterable=check_filterable,
  File "E:\PycharmProjects\yyapi\venv\lib\site-packages\django\db\models\sql\query.py", line 1319, in build_filter
    condition = self.build_lookup(lookups, col, value)
  File "E:\PycharmProjects\yyapi\venv\lib\site-packages\django\db\models\sql\query.py", line 1165, in build_lookup
    lookup = lookup_class(lhs, rhs)
  File "E:\PycharmProjects\yyapi\venv\lib\site-packages\django\db\models\lookups.py", line 24, in __init__
    self.rhs = self.get_prep_lookup()
  File "E:\PycharmProjects\yyapi\venv\lib\site-packages\django\db\models\lookups.py", line 76, in get_prep_lookup
    return self.lhs.output_field.get_prep_value(self.rhs)
  File "E:\PycharmProjects\yyapi\venv\lib\site-packages\django\db\models\fields\__init__.py", line 1778, in get_prep_value
    ) from e
ValueError: Field 'id' expected a number but got ''.
[2021-08-17 14:21:40,398][Thread-2:10840][task_id:django.request][log.py:230][ERROR][Internal Server Error: /global_data_save/]
Traceback (most recent call last):
  File "E:\PycharmProjects\yyapi\venv\lib\site-packages\django\db\models\fields\__init__.py", line 1774, in get_prep_value
    return int(value)
ValueError: invalid literal for int() with base 10: ''

The above exception was the direct cause of the following exception:

Traceback (most recent call last):
  File "E:\PycharmProjects\yyapi\venv\lib\site-packages\django\core\handlers\exception.py", line 47, in inner
    response = get_response(request)
  File "E:\PycharmProjects\yyapi\venv\lib\site-packages\django\core\handlers\base.py", line 179, in _get_response
    response = wrapped_callback(request, *callback_args, **callback_kwargs)
  File "E:\PycharmProjects\yyapi\MyApp\views.py", line 1453, in global_data_save
    DB_global_data.objects.filter(id=global_id).update(name=global_name,data=global_data)
  File "E:\PycharmProjects\yyapi\venv\lib\site-packages\django\db\models\manager.py", line 85, in manager_method
    return getattr(self.get_queryset(), name)(*args, **kwargs)
  File "E:\PycharmProjects\yyapi\venv\lib\site-packages\django\db\models\query.py", line 942, in filter
    return self._filter_or_exclude(False, *args, **kwargs)
  File "E:\PycharmProjects\yyapi\venv\lib\site-packages\django\db\models\query.py", line 962, in _filter_or_exclude
    clone._filter_or_exclude_inplace(negate, *args, **kwargs)
  File "E:\PycharmProjects\yyapi\venv\lib\site-packages\django\db\models\query.py", line 969, in _filter_or_exclude_inplace
    self._query.add_q(Q(*args, **kwargs))
  File "E:\PycharmProjects\yyapi\venv\lib\site-packages\django\db\models\sql\query.py", line 1358, in add_q
    clause, _ = self._add_q(q_object, self.used_aliases)
  File "E:\PycharmProjects\yyapi\venv\lib\site-packages\django\db\models\sql\query.py", line 1380, in _add_q
    split_subq=split_subq, check_filterable=check_filterable,
  File "E:\PycharmProjects\yyapi\venv\lib\site-packages\django\db\models\sql\query.py", line 1319, in build_filter
    condition = self.build_lookup(lookups, col, value)
  File "E:\PycharmProjects\yyapi\venv\lib\site-packages\django\db\models\sql\query.py", line 1165, in build_lookup
    lookup = lookup_class(lhs, rhs)
  File "E:\PycharmProjects\yyapi\venv\lib\site-packages\django\db\models\lookups.py", line 24, in __init__
    self.rhs = self.get_prep_lookup()
  File "E:\PycharmProjects\yyapi\venv\lib\site-packages\django\db\models\lookups.py", line 76, in get_prep_lookup
    return self.lhs.output_field.get_prep_value(self.rhs)
  File "E:\PycharmProjects\yyapi\venv\lib\site-packages\django\db\models\fields\__init__.py", line 1778, in get_prep_value
    ) from e
ValueError: Field 'id' expected a number but got ''.
[2021-08-17 14:22:38,991][Thread-3:10932][task_id:django.request][log.py:230][ERROR][Internal Server Error: /global_data_save/]
Traceback (most recent call last):
  File "E:\PycharmProjects\yyapi\venv\lib\site-packages\django\db\models\fields\__init__.py", line 1774, in get_prep_value
    return int(value)
ValueError: invalid literal for int() with base 10: ''

The above exception was the direct cause of the following exception:

Traceback (most recent call last):
  File "E:\PycharmProjects\yyapi\venv\lib\site-packages\django\core\handlers\exception.py", line 47, in inner
    response = get_response(request)
  File "E:\PycharmProjects\yyapi\venv\lib\site-packages\django\core\handlers\base.py", line 179, in _get_response
    response = wrapped_callback(request, *callback_args, **callback_kwargs)
  File "E:\PycharmProjects\yyapi\MyApp\views.py", line 1453, in global_data_save
    DB_global_data.objects.filter(id=global_id).update(name=global_name,data=global_data)
  File "E:\PycharmProjects\yyapi\venv\lib\site-packages\django\db\models\manager.py", line 85, in manager_method
    return getattr(self.get_queryset(), name)(*args, **kwargs)
  File "E:\PycharmProjects\yyapi\venv\lib\site-packages\django\db\models\query.py", line 942, in filter
    return self._filter_or_exclude(False, *args, **kwargs)
  File "E:\PycharmProjects\yyapi\venv\lib\site-packages\django\db\models\query.py", line 962, in _filter_or_exclude
    clone._filter_or_exclude_inplace(negate, *args, **kwargs)
  File "E:\PycharmProjects\yyapi\venv\lib\site-packages\django\db\models\query.py", line 969, in _filter_or_exclude_inplace
    self._query.add_q(Q(*args, **kwargs))
  File "E:\PycharmProjects\yyapi\venv\lib\site-packages\django\db\models\sql\query.py", line 1358, in add_q
    clause, _ = self._add_q(q_object, self.used_aliases)
  File "E:\PycharmProjects\yyapi\venv\lib\site-packages\django\db\models\sql\query.py", line 1380, in _add_q
    split_subq=split_subq, check_filterable=check_filterable,
  File "E:\PycharmProjects\yyapi\venv\lib\site-packages\django\db\models\sql\query.py", line 1319, in build_filter
    condition = self.build_lookup(lookups, col, value)
  File "E:\PycharmProjects\yyapi\venv\lib\site-packages\django\db\models\sql\query.py", line 1165, in build_lookup
    lookup = lookup_class(lhs, rhs)
  File "E:\PycharmProjects\yyapi\venv\lib\site-packages\django\db\models\lookups.py", line 24, in __init__
    self.rhs = self.get_prep_lookup()
  File "E:\PycharmProjects\yyapi\venv\lib\site-packages\django\db\models\lookups.py", line 76, in get_prep_lookup
    return self.lhs.output_field.get_prep_value(self.rhs)
  File "E:\PycharmProjects\yyapi\venv\lib\site-packages\django\db\models\fields\__init__.py", line 1778, in get_prep_value
    ) from e
ValueError: Field 'id' expected a number but got ''.
[2021-08-17 14:22:43,466][Thread-3:10932][task_id:django.request][log.py:230][ERROR][Internal Server Error: /global_data_save/]
Traceback (most recent call last):
  File "E:\PycharmProjects\yyapi\venv\lib\site-packages\django\db\models\fields\__init__.py", line 1774, in get_prep_value
    return int(value)
ValueError: invalid literal for int() with base 10: ''

The above exception was the direct cause of the following exception:

Traceback (most recent call last):
  File "E:\PycharmProjects\yyapi\venv\lib\site-packages\django\core\handlers\exception.py", line 47, in inner
    response = get_response(request)
  File "E:\PycharmProjects\yyapi\venv\lib\site-packages\django\core\handlers\base.py", line 179, in _get_response
    response = wrapped_callback(request, *callback_args, **callback_kwargs)
  File "E:\PycharmProjects\yyapi\MyApp\views.py", line 1453, in global_data_save
    DB_global_data.objects.filter(id=global_id).update(name=global_name,data=global_data)
  File "E:\PycharmProjects\yyapi\venv\lib\site-packages\django\db\models\manager.py", line 85, in manager_method
    return getattr(self.get_queryset(), name)(*args, **kwargs)
  File "E:\PycharmProjects\yyapi\venv\lib\site-packages\django\db\models\query.py", line 942, in filter
    return self._filter_or_exclude(False, *args, **kwargs)
  File "E:\PycharmProjects\yyapi\venv\lib\site-packages\django\db\models\query.py", line 962, in _filter_or_exclude
    clone._filter_or_exclude_inplace(negate, *args, **kwargs)
  File "E:\PycharmProjects\yyapi\venv\lib\site-packages\django\db\models\query.py", line 969, in _filter_or_exclude_inplace
    self._query.add_q(Q(*args, **kwargs))
  File "E:\PycharmProjects\yyapi\venv\lib\site-packages\django\db\models\sql\query.py", line 1358, in add_q
    clause, _ = self._add_q(q_object, self.used_aliases)
  File "E:\PycharmProjects\yyapi\venv\lib\site-packages\django\db\models\sql\query.py", line 1380, in _add_q
    split_subq=split_subq, check_filterable=check_filterable,
  File "E:\PycharmProjects\yyapi\venv\lib\site-packages\django\db\models\sql\query.py", line 1319, in build_filter
    condition = self.build_lookup(lookups, col, value)
  File "E:\PycharmProjects\yyapi\venv\lib\site-packages\django\db\models\sql\query.py", line 1165, in build_lookup
    lookup = lookup_class(lhs, rhs)
  File "E:\PycharmProjects\yyapi\venv\lib\site-packages\django\db\models\lookups.py", line 24, in __init__
    self.rhs = self.get_prep_lookup()
  File "E:\PycharmProjects\yyapi\venv\lib\site-packages\django\db\models\lookups.py", line 76, in get_prep_lookup
    return self.lhs.output_field.get_prep_value(self.rhs)
  File "E:\PycharmProjects\yyapi\venv\lib\site-packages\django\db\models\fields\__init__.py", line 1778, in get_prep_value
    ) from e
ValueError: Field 'id' expected a number but got ''.
[2021-08-17 14:22:48,508][Thread-3:10932][task_id:django.request][log.py:230][ERROR][Internal Server Error: /global_data_save/]
Traceback (most recent call last):
  File "E:\PycharmProjects\yyapi\venv\lib\site-packages\django\db\models\fields\__init__.py", line 1774, in get_prep_value
    return int(value)
ValueError: invalid literal for int() with base 10: ''

The above exception was the direct cause of the following exception:

Traceback (most recent call last):
  File "E:\PycharmProjects\yyapi\venv\lib\site-packages\django\core\handlers\exception.py", line 47, in inner
    response = get_response(request)
  File "E:\PycharmProjects\yyapi\venv\lib\site-packages\django\core\handlers\base.py", line 179, in _get_response
    response = wrapped_callback(request, *callback_args, **callback_kwargs)
  File "E:\PycharmProjects\yyapi\MyApp\views.py", line 1453, in global_data_save
    DB_global_data.objects.filter(id=global_id).update(name=global_name,data=global_data)
  File "E:\PycharmProjects\yyapi\venv\lib\site-packages\django\db\models\manager.py", line 85, in manager_method
    return getattr(self.get_queryset(), name)(*args, **kwargs)
  File "E:\PycharmProjects\yyapi\venv\lib\site-packages\django\db\models\query.py", line 942, in filter
    return self._filter_or_exclude(False, *args, **kwargs)
  File "E:\PycharmProjects\yyapi\venv\lib\site-packages\django\db\models\query.py", line 962, in _filter_or_exclude
    clone._filter_or_exclude_inplace(negate, *args, **kwargs)
  File "E:\PycharmProjects\yyapi\venv\lib\site-packages\django\db\models\query.py", line 969, in _filter_or_exclude_inplace
    self._query.add_q(Q(*args, **kwargs))
  File "E:\PycharmProjects\yyapi\venv\lib\site-packages\django\db\models\sql\query.py", line 1358, in add_q
    clause, _ = self._add_q(q_object, self.used_aliases)
  File "E:\PycharmProjects\yyapi\venv\lib\site-packages\django\db\models\sql\query.py", line 1380, in _add_q
    split_subq=split_subq, check_filterable=check_filterable,
  File "E:\PycharmProjects\yyapi\venv\lib\site-packages\django\db\models\sql\query.py", line 1319, in build_filter
    condition = self.build_lookup(lookups, col, value)
  File "E:\PycharmProjects\yyapi\venv\lib\site-packages\django\db\models\sql\query.py", line 1165, in build_lookup
    lookup = lookup_class(lhs, rhs)
  File "E:\PycharmProjects\yyapi\venv\lib\site-packages\django\db\models\lookups.py", line 24, in __init__
    self.rhs = self.get_prep_lookup()
  File "E:\PycharmProjects\yyapi\venv\lib\site-packages\django\db\models\lookups.py", line 76, in get_prep_lookup
    return self.lhs.output_field.get_prep_value(self.rhs)
  File "E:\PycharmProjects\yyapi\venv\lib\site-packages\django\db\models\fields\__init__.py", line 1778, in get_prep_value
    ) from e
ValueError: Field 'id' expected a number but got ''.
[2021-08-17 14:23:07,552][Thread-3:10932][task_id:django.request][log.py:230][ERROR][Internal Server Error: /global_data_save/]
Traceback (most recent call last):
  File "E:\PycharmProjects\yyapi\venv\lib\site-packages\django\db\models\fields\__init__.py", line 1774, in get_prep_value
    return int(value)
ValueError: invalid literal for int() with base 10: ''

The above exception was the direct cause of the following exception:

Traceback (most recent call last):
  File "E:\PycharmProjects\yyapi\venv\lib\site-packages\django\core\handlers\exception.py", line 47, in inner
    response = get_response(request)
  File "E:\PycharmProjects\yyapi\venv\lib\site-packages\django\core\handlers\base.py", line 179, in _get_response
    response = wrapped_callback(request, *callback_args, **callback_kwargs)
  File "E:\PycharmProjects\yyapi\MyApp\views.py", line 1453, in global_data_save
    DB_global_data.objects.filter(id=global_id).update(name=global_name,data=global_data)
  File "E:\PycharmProjects\yyapi\venv\lib\site-packages\django\db\models\manager.py", line 85, in manager_method
    return getattr(self.get_queryset(), name)(*args, **kwargs)
  File "E:\PycharmProjects\yyapi\venv\lib\site-packages\django\db\models\query.py", line 942, in filter
    return self._filter_or_exclude(False, *args, **kwargs)
  File "E:\PycharmProjects\yyapi\venv\lib\site-packages\django\db\models\query.py", line 962, in _filter_or_exclude
    clone._filter_or_exclude_inplace(negate, *args, **kwargs)
  File "E:\PycharmProjects\yyapi\venv\lib\site-packages\django\db\models\query.py", line 969, in _filter_or_exclude_inplace
    self._query.add_q(Q(*args, **kwargs))
  File "E:\PycharmProjects\yyapi\venv\lib\site-packages\django\db\models\sql\query.py", line 1358, in add_q
    clause, _ = self._add_q(q_object, self.used_aliases)
  File "E:\PycharmProjects\yyapi\venv\lib\site-packages\django\db\models\sql\query.py", line 1380, in _add_q
    split_subq=split_subq, check_filterable=check_filterable,
  File "E:\PycharmProjects\yyapi\venv\lib\site-packages\django\db\models\sql\query.py", line 1319, in build_filter
    condition = self.build_lookup(lookups, col, value)
  File "E:\PycharmProjects\yyapi\venv\lib\site-packages\django\db\models\sql\query.py", line 1165, in build_lookup
    lookup = lookup_class(lhs, rhs)
  File "E:\PycharmProjects\yyapi\venv\lib\site-packages\django\db\models\lookups.py", line 24, in __init__
    self.rhs = self.get_prep_lookup()
  File "E:\PycharmProjects\yyapi\venv\lib\site-packages\django\db\models\lookups.py", line 76, in get_prep_lookup
    return self.lhs.output_field.get_prep_value(self.rhs)
  File "E:\PycharmProjects\yyapi\venv\lib\site-packages\django\db\models\fields\__init__.py", line 1778, in get_prep_value
    ) from e
ValueError: Field 'id' expected a number but got ''.
[2021-08-17 14:23:41,487][Thread-3:10932][task_id:django.request][log.py:230][ERROR][Internal Server Error: /global_data_save/]
Traceback (most recent call last):
  File "E:\PycharmProjects\yyapi\venv\lib\site-packages\django\db\models\fields\__init__.py", line 1774, in get_prep_value
    return int(value)
ValueError: invalid literal for int() with base 10: ''

The above exception was the direct cause of the following exception:

Traceback (most recent call last):
  File "E:\PycharmProjects\yyapi\venv\lib\site-packages\django\core\handlers\exception.py", line 47, in inner
    response = get_response(request)
  File "E:\PycharmProjects\yyapi\venv\lib\site-packages\django\core\handlers\base.py", line 179, in _get_response
    response = wrapped_callback(request, *callback_args, **callback_kwargs)
  File "E:\PycharmProjects\yyapi\MyApp\views.py", line 1453, in global_data_save
    DB_global_data.objects.filter(id=global_id).update(name=global_name,data=global_data)
  File "E:\PycharmProjects\yyapi\venv\lib\site-packages\django\db\models\manager.py", line 85, in manager_method
    return getattr(self.get_queryset(), name)(*args, **kwargs)
  File "E:\PycharmProjects\yyapi\venv\lib\site-packages\django\db\models\query.py", line 942, in filter
    return self._filter_or_exclude(False, *args, **kwargs)
  File "E:\PycharmProjects\yyapi\venv\lib\site-packages\django\db\models\query.py", line 962, in _filter_or_exclude
    clone._filter_or_exclude_inplace(negate, *args, **kwargs)
  File "E:\PycharmProjects\yyapi\venv\lib\site-packages\django\db\models\query.py", line 969, in _filter_or_exclude_inplace
    self._query.add_q(Q(*args, **kwargs))
  File "E:\PycharmProjects\yyapi\venv\lib\site-packages\django\db\models\sql\query.py", line 1358, in add_q
    clause, _ = self._add_q(q_object, self.used_aliases)
  File "E:\PycharmProjects\yyapi\venv\lib\site-packages\django\db\models\sql\query.py", line 1380, in _add_q
    split_subq=split_subq, check_filterable=check_filterable,
  File "E:\PycharmProjects\yyapi\venv\lib\site-packages\django\db\models\sql\query.py", line 1319, in build_filter
    condition = self.build_lookup(lookups, col, value)
  File "E:\PycharmProjects\yyapi\venv\lib\site-packages\django\db\models\sql\query.py", line 1165, in build_lookup
    lookup = lookup_class(lhs, rhs)
  File "E:\PycharmProjects\yyapi\venv\lib\site-packages\django\db\models\lookups.py", line 24, in __init__
    self.rhs = self.get_prep_lookup()
  File "E:\PycharmProjects\yyapi\venv\lib\site-packages\django\db\models\lookups.py", line 76, in get_prep_lookup
    return self.lhs.output_field.get_prep_value(self.rhs)
  File "E:\PycharmProjects\yyapi\venv\lib\site-packages\django\db\models\fields\__init__.py", line 1778, in get_prep_value
    ) from e
ValueError: Field 'id' expected a number but got ''.
[2021-08-17 17:41:47,147][Thread-19:18724][task_id:django.request][log.py:230][ERROR][Internal Server Error: /register_action/]
Traceback (most recent call last):
  File "E:\PycharmProjects\yyapi\venv\lib\site-packages\django\utils\datastructures.py", line 76, in __getitem__
    list_ = super().__getitem__(key)
KeyError: 'username'

During handling of the above exception, another exception occurred:

Traceback (most recent call last):
  File "E:\PycharmProjects\yyapi\venv\lib\site-packages\django\core\handlers\exception.py", line 47, in inner
    response = get_response(request)
  File "E:\PycharmProjects\yyapi\venv\lib\site-packages\django\core\handlers\base.py", line 179, in _get_response
    response = wrapped_callback(request, *callback_args, **callback_kwargs)
  File "E:\PycharmProjects\yyapi\MyApp\views.py", line 215, in register_action
    u_name = request.GET['username']
  File "E:\PycharmProjects\yyapi\venv\lib\site-packages\django\utils\datastructures.py", line 78, in __getitem__
    raise MultiValueDictKeyError(key)
django.utils.datastructures.MultiValueDictKeyError: 'username'
[2021-08-17 17:42:40,503][Thread-20:6376][task_id:django.request][log.py:230][ERROR][Internal Server Error: /register_action/]
Traceback (most recent call last):
  File "E:\PycharmProjects\yyapi\venv\lib\site-packages\django\utils\datastructures.py", line 76, in __getitem__
    list_ = super().__getitem__(key)
KeyError: 'username'

During handling of the above exception, another exception occurred:

Traceback (most recent call last):
  File "E:\PycharmProjects\yyapi\venv\lib\site-packages\django\core\handlers\exception.py", line 47, in inner
    response = get_response(request)
  File "E:\PycharmProjects\yyapi\venv\lib\site-packages\django\core\handlers\base.py", line 179, in _get_response
    response = wrapped_callback(request, *callback_args, **callback_kwargs)
  File "E:\PycharmProjects\yyapi\MyApp\views.py", line 215, in register_action
    u_name = request.GET['username']
  File "E:\PycharmProjects\yyapi\venv\lib\site-packages\django\utils\datastructures.py", line 78, in __getitem__
    raise MultiValueDictKeyError(key)
django.utils.datastructures.MultiValueDictKeyError: 'username'
[2021-08-17 17:43:44,538][Thread-28:20912][task_id:django.request][log.py:230][ERROR][Internal Server Error: /register_action/]
Traceback (most recent call last):
  File "E:\PycharmProjects\yyapi\venv\lib\site-packages\django\utils\datastructures.py", line 76, in __getitem__
    list_ = super().__getitem__(key)
KeyError: 'username'

During handling of the above exception, another exception occurred:

Traceback (most recent call last):
  File "E:\PycharmProjects\yyapi\venv\lib\site-packages\django\core\handlers\exception.py", line 47, in inner
    response = get_response(request)
  File "E:\PycharmProjects\yyapi\venv\lib\site-packages\django\core\handlers\base.py", line 179, in _get_response
    response = wrapped_callback(request, *callback_args, **callback_kwargs)
  File "E:\PycharmProjects\yyapi\MyApp\views.py", line 215, in register_action
    u_name = request.GET['username']
  File "E:\PycharmProjects\yyapi\venv\lib\site-packages\django\utils\datastructures.py", line 78, in __getitem__
    raise MultiValueDictKeyError(key)
django.utils.datastructures.MultiValueDictKeyError: 'username'
[2021-08-17 17:43:47,587][Thread-29:6140][task_id:django.request][log.py:230][ERROR][Internal Server Error: /register_action/]
Traceback (most recent call last):
  File "E:\PycharmProjects\yyapi\venv\lib\site-packages\django\utils\datastructures.py", line 76, in __getitem__
    list_ = super().__getitem__(key)
KeyError: 'username'

During handling of the above exception, another exception occurred:

Traceback (most recent call last):
  File "E:\PycharmProjects\yyapi\venv\lib\site-packages\django\core\handlers\exception.py", line 47, in inner
    response = get_response(request)
  File "E:\PycharmProjects\yyapi\venv\lib\site-packages\django\core\handlers\base.py", line 179, in _get_response
    response = wrapped_callback(request, *callback_args, **callback_kwargs)
  File "E:\PycharmProjects\yyapi\MyApp\views.py", line 215, in register_action
    u_name = request.GET['username']
  File "E:\PycharmProjects\yyapi\venv\lib\site-packages\django\utils\datastructures.py", line 78, in __getitem__
    raise MultiValueDictKeyError(key)
django.utils.datastructures.MultiValueDictKeyError: 'username'
[2021-08-17 17:44:50,759][Thread-5:24740][task_id:django.request][log.py:230][ERROR][Internal Server Error: /register_action/]
Traceback (most recent call last):
  File "E:\PycharmProjects\yyapi\venv\lib\site-packages\django\utils\datastructures.py", line 76, in __getitem__
    list_ = super().__getitem__(key)
KeyError: 'username'

During handling of the above exception, another exception occurred:

Traceback (most recent call last):
  File "E:\PycharmProjects\yyapi\venv\lib\site-packages\django\core\handlers\exception.py", line 47, in inner
    response = get_response(request)
  File "E:\PycharmProjects\yyapi\venv\lib\site-packages\django\core\handlers\base.py", line 179, in _get_response
    response = wrapped_callback(request, *callback_args, **callback_kwargs)
  File "E:\PycharmProjects\yyapi\MyApp\views.py", line 215, in register_action
    u_name = request.GET['username']
  File "E:\PycharmProjects\yyapi\venv\lib\site-packages\django\utils\datastructures.py", line 78, in __getitem__
    raise MultiValueDictKeyError(key)
django.utils.datastructures.MultiValueDictKeyError: 'username'
[2021-08-17 17:44:53,799][Thread-6:15524][task_id:django.request][log.py:230][ERROR][Internal Server Error: /register_action/]
Traceback (most recent call last):
  File "E:\PycharmProjects\yyapi\venv\lib\site-packages\django\utils\datastructures.py", line 76, in __getitem__
    list_ = super().__getitem__(key)
KeyError: 'username'

During handling of the above exception, another exception occurred:

Traceback (most recent call last):
  File "E:\PycharmProjects\yyapi\venv\lib\site-packages\django\core\handlers\exception.py", line 47, in inner
    response = get_response(request)
  File "E:\PycharmProjects\yyapi\venv\lib\site-packages\django\core\handlers\base.py", line 179, in _get_response
    response = wrapped_callback(request, *callback_args, **callback_kwargs)
  File "E:\PycharmProjects\yyapi\MyApp\views.py", line 215, in register_action
    u_name = request.GET['username']
  File "E:\PycharmProjects\yyapi\venv\lib\site-packages\django\utils\datastructures.py", line 78, in __getitem__
    raise MultiValueDictKeyError(key)
django.utils.datastructures.MultiValueDictKeyError: 'username'
[2021-08-17 17:45:28,402][Thread-8:16752][task_id:django.request][log.py:230][ERROR][Internal Server Error: /register_action/]
Traceback (most recent call last):
  File "E:\PycharmProjects\yyapi\venv\lib\site-packages\django\utils\datastructures.py", line 76, in __getitem__
    list_ = super().__getitem__(key)
KeyError: 'username'

During handling of the above exception, another exception occurred:

Traceback (most recent call last):
  File "E:\PycharmProjects\yyapi\venv\lib\site-packages\django\core\handlers\exception.py", line 47, in inner
    response = get_response(request)
  File "E:\PycharmProjects\yyapi\venv\lib\site-packages\django\core\handlers\base.py", line 179, in _get_response
    response = wrapped_callback(request, *callback_args, **callback_kwargs)
  File "E:\PycharmProjects\yyapi\MyApp\views.py", line 215, in register_action
    u_name = request.GET['username']
  File "E:\PycharmProjects\yyapi\venv\lib\site-packages\django\utils\datastructures.py", line 78, in __getitem__
    raise MultiValueDictKeyError(key)
django.utils.datastructures.MultiValueDictKeyError: 'username'
[2021-08-17 17:45:31,453][Thread-9:15056][task_id:django.request][log.py:230][ERROR][Internal Server Error: /register_action/]
Traceback (most recent call last):
  File "E:\PycharmProjects\yyapi\venv\lib\site-packages\django\utils\datastructures.py", line 76, in __getitem__
    list_ = super().__getitem__(key)
KeyError: 'username'

During handling of the above exception, another exception occurred:

Traceback (most recent call last):
  File "E:\PycharmProjects\yyapi\venv\lib\site-packages\django\core\handlers\exception.py", line 47, in inner
    response = get_response(request)
  File "E:\PycharmProjects\yyapi\venv\lib\site-packages\django\core\handlers\base.py", line 179, in _get_response
    response = wrapped_callback(request, *callback_args, **callback_kwargs)
  File "E:\PycharmProjects\yyapi\MyApp\views.py", line 215, in register_action
    u_name = request.GET['username']
  File "E:\PycharmProjects\yyapi\venv\lib\site-packages\django\utils\datastructures.py", line 78, in __getitem__
    raise MultiValueDictKeyError(key)
django.utils.datastructures.MultiValueDictKeyError: 'username'
[2021-08-17 17:46:03,390][Thread-2:20896][task_id:django.request][log.py:230][ERROR][Internal Server Error: /register_action/]
Traceback (most recent call last):
  File "E:\PycharmProjects\yyapi\venv\lib\site-packages\django\utils\datastructures.py", line 76, in __getitem__
    list_ = super().__getitem__(key)
KeyError: 'username'

During handling of the above exception, another exception occurred:

Traceback (most recent call last):
  File "E:\PycharmProjects\yyapi\venv\lib\site-packages\django\core\handlers\exception.py", line 47, in inner
    response = get_response(request)
  File "E:\PycharmProjects\yyapi\venv\lib\site-packages\django\core\handlers\base.py", line 179, in _get_response
    response = wrapped_callback(request, *callback_args, **callback_kwargs)
  File "E:\PycharmProjects\yyapi\MyApp\views.py", line 215, in register_action
    u_name = request.GET['username']
  File "E:\PycharmProjects\yyapi\venv\lib\site-packages\django\utils\datastructures.py", line 78, in __getitem__
    raise MultiValueDictKeyError(key)
django.utils.datastructures.MultiValueDictKeyError: 'username'
[2021-08-17 17:46:06,437][Thread-3:10920][task_id:django.request][log.py:230][ERROR][Internal Server Error: /register_action/]
Traceback (most recent call last):
  File "E:\PycharmProjects\yyapi\venv\lib\site-packages\django\utils\datastructures.py", line 76, in __getitem__
    list_ = super().__getitem__(key)
KeyError: 'username'

During handling of the above exception, another exception occurred:

Traceback (most recent call last):
  File "E:\PycharmProjects\yyapi\venv\lib\site-packages\django\core\handlers\exception.py", line 47, in inner
    response = get_response(request)
  File "E:\PycharmProjects\yyapi\venv\lib\site-packages\django\core\handlers\base.py", line 179, in _get_response
    response = wrapped_callback(request, *callback_args, **callback_kwargs)
  File "E:\PycharmProjects\yyapi\MyApp\views.py", line 215, in register_action
    u_name = request.GET['username']
  File "E:\PycharmProjects\yyapi\venv\lib\site-packages\django\utils\datastructures.py", line 78, in __getitem__
    raise MultiValueDictKeyError(key)
django.utils.datastructures.MultiValueDictKeyError: 'username'
